Workbook

Sheet 教师安排
A1: 江河高级中学2026年春季学期课务安排表
A2: 科目 | B2: 高一（1）班 | C2: 高一（2）班 | D2: 高一（3）班 | E2: 高一（4）班 | F2: 高二（1）班 | G2: 高二（2）班 | H2: 高二（3）班 | I2: 高二（4）班 | J2: 高二（5）班 | K2: 高二（6）班 | L2: 高二（7）班 | M2: 高二（8）班 | N2: 高二（9）班 | O2: 高二（10）班 | P2: 高二（11）班 | Q2: 高一英语（1）班 | R2: 高一英语（2）班 | S2: 高一俄语（1）班 | T2: 高一俄语（2）班 | U2: 高二俄语（2）班 | V2: 高二俄语（1）班 | W2: 高二英语（1）班 | X2: 高二英语（2）班 | Y2: 高二英语（3）班
A3: 语文 | B3: 杨彬 | C3: 史振塞 | D3: 杨彬 | E3: 史振塞 | F3: 张冰雪 | G3: 姜媛媛 | H3: 王雪莲 | I3: 路睿 | J3: 张冰雪 | K3: 王菲 | L3: 路睿 | M3: 王雪莲 | N3: 王菲 | O3: 姜媛媛 | P3: 路睿
A4: 数学 | B4: 侯淑贤 | C4: 姚来朋 | D4: 姚来朋 | E4: 侯淑贤 | F4: 赵雪敏 | G4: 王露 | H4: 范林林 | I4: 高文凤 | J4: 赵雪敏 | K4: 孙娜 | L4: 范林林 | M4: 孙娜 | N4: 范林林 | O4: 王露 | P4: 高文凤
A5: 外语 | B5: 岳/厉 | C5: 岳/厉 | D5: 岳/厉 | E5: 岳/厉 | F5: 王灼 | G5: 翟淑玮 | H5: 韩丽梅 | I5: 宋平 | J5: 王灼 | K5: 胡存想 | L5: 王/宋/翟/胡 | M5: 韩/宋/翟/胡 | N5: 宋/韩/王 | O5: 翟/韩/王 | P5: 胡/韩/王
A6: 物理 | B6: 康波 | C6: 张雨晴 | D6: 张雨晴 | E6: 康波 | F6: 孙存义 | G6: 孙存义 | H6: 孙存义 | I6: 康波
A7: 化学 | B7: 马崇庆 | C7: 宋开元 | D7: 宋开元 | E7: 马崇庆 | F7: 李振铎 | G7: 李振铎 | H7: 马崇庆 | I7: 宋开元
A8: 生物 | B8: 周兴玲 | C8: 周兴玲 | D8: 周兴玲 | E8: 周兴玲 | F8: 刘腾 | G8: 蒋心言 | J8: 刘腾 | K8: 蒋心言
A9: 历史 | B9: 李雯 | C9: 田凤美 | D9: 李雯 | E9: 李雯 | J9: 田凤美 | K9: 董艳华 | L9: 田凤美 | M9: 董艳华 | N9: 夏文杰 | O9: 董艳华 | P9: 夏文杰
A10: 政治 | B10: 刘珊珊 | C10: 刘珊珊 | D10: 张雯皓 | E10: 刘珊珊 | L10: 张雯皓 | M10: 张鑫 | N10: 李浩然 | O10: 李浩然 | P10: 张鑫
A11: 地理 | B11: 李会玲 | C11: 李会玲 | D11: 李会玲 | E11: 李会玲 | H11: 孙锦锦 | I11: 孙秋杰 | J11: 王硕 | K11: 孙秋杰 | L11: 孙锦锦 | M11: 王硕 | N11: 王硕 | O11: 孙锦锦 | P11: 孙秋杰
A12: 体育 | B12: 王庆超 | C12: 王庆超 | D12: 王庆超 | E12: 王庆超 | F12: 袁奇 | G12: 刘天骄 | H12: 袁奇 | I12: 刘天骄 | J12: 袁奇 | K12: 刘天骄 | L12: 袁奇 | M12: 刘天骄 | N12: 袁奇 | O12: 刘天骄 | P12: 袁奇
A13: 音乐 | B13: 李冰慧 | C13: 李冰慧 | D13: 李冰慧 | E13: 李冰慧
A14: 美术 | B14: 张苏 | C14: 张苏 | D14: 张苏 | E14: 张苏
A15: 信息 | B15: 张喆 | C15: 张喆 | D15: 张喆 | E15: 张喆 | F15: 孙显阳 | G15: 张喆 | H15: 孙显阳 | I15: 张喆 | J15: 孙显阳 | K15: 张喆 | L15: 孙显阳 | M15: 张喆 | N15: 孙显阳 | O15: 张喆 | P15: 孙显阳
A16: 通用 | F16: 孙显阳 | G16: 孙显阳 | H16: 孙显阳 | I16: 孙显阳 | J16: 孙显阳 | K16: 孙显阳 | L16: 孙显阳 | M16: 孙显阳 | N16: 孙显阳 | O16: 孙显阳 | P16: 孙显阳
A17: 班会 | B17: 侯淑贤 | C17: 田凤美 | D17: 厉彦龙 | E17: 王庆超 | F17: 李振铎 | G17: 蒋心言 | H17: 王雪莲 | I17: 高文凤 | J17: 张冰雪 | K17: 孙娜 | L17: 刘天骄 | M17: 韩丽梅 | N17: 王菲 | O17: 翟淑玮 | P17: 张鑫
A18: 自习
A19: 自习（语） | B19: 杨彬 | C19: 史振塞 | D19: 杨彬 | E19: 史振塞 | F19: 张冰雪 | G19: 姜媛媛 | H19: 王雪莲 | I19: 路睿 | J19: 张冰雪 | K19: 王菲 | L19: 路睿 | M19: 王雪莲 | N19: 王菲 | O19: 姜媛媛 | P19: 路睿
A20: 自习（数） | B20: 侯淑贤 | C20: 姚来朋 | D20: 姚来朋 | E20: 侯淑贤 | F20: 赵雪敏 | G20: 王露 | H20: 范林林 | I20: 高文凤 | J20: 赵雪敏 | K20: 孙娜 | L20: 范林林 | M20: 孙娜 | N20: 范林林 | O20: 王露 | P20: 高文凤
A21: 自习（外） | B21: 岳/厉 | C21: 岳/厉 | D21: 岳/厉 | E21: 岳/厉 | F21: 王灼 | G21: 翟淑玮 | H21: 韩丽梅 | I21: 宋平 | J21: 王灼 | K21: 胡存想 | L21: 王/宋/翟/胡 | M21: 韩/宋/翟/胡 | N21: 宋/韩/王 | O21: 翟/韩/王 | P21: 胡/韩/王
A22: 自习（物） | B22: 康波 | C22: 张雨晴 | D22: 张雨晴 | E22: 康波 | F22: 孙存义 | G22: 孙存义 | H22: 孙存义 | I22: 康波
A23: 自习（化） | B23: 马崇庆 | C23: 宋开元 | D23: 宋开元 | E23: 马崇庆 | F23: 李振铎 | G23: 李振铎 | H23: 马崇庆 | I23: 宋开元
A24: 自习（生） | B24: 周兴玲 | C24: 周兴玲 | D24: 周兴玲 | E24: 周兴玲 | F24: 刘腾 | G24: 蒋心言 | J24: 刘腾 | K24: 蒋心言
A25: 自习（历） | B25: 李雯 | C25: 田凤美 | D25: 李雯 | E25: 李雯 | J25: 田凤美 | K25: 董艳华 | L25: 田凤美 | M25: 董艳华 | N25: 夏文杰 | O25: 董艳华 | P25: 夏文杰
A26: 自习（政） | B26: 刘珊珊 | C26: 刘珊珊 | D26: 张雯皓 | E26: 刘珊珊 | L26: 张雯皓 | M26: 张鑫 | N26: 李浩然 | O26: 李浩然 | P26: 张鑫
A27: 自习（地） | B27: 李会玲 | C27: 李会玲 | D27: 李会玲 | E27: 李会玲 | H27: 孙锦锦 | I27: 孙秋杰 | J27: 王硕 | K27: 孙秋杰 | L27: 孙锦锦 | M27: 王硕 | N27: 王硕 | O27: 孙锦锦 | P27: 孙秋杰
A28: 政史 | B28: 刘珊珊 | C28: 刘珊珊 | D28: 李雯 | E28: 李雯
A29: 理化 | B29: 张雨晴 | C29: 张雨晴 | D29: 马崇庆 | E29: 宋开元
A30: 地生 | B30: 李会玲 | C30: 李会玲 | D30: 蒋心言 | E30: 刘腾
A31: 听力 | B31: 岳/厉 | C31: 岳/厉 | D31: 岳/厉 | E31: 岳/厉 | F31: 王灼 | G31: 翟淑玮 | H31: 韩丽梅 | I31: 宋平 | J31: 王灼 | K31: 胡存想 | L31: 王/宋/翟/胡 | M31: 韩/宋/翟/胡 | N31: 宋/韩/王 | O31: 翟/韩/王 | P31: 胡/韩/王
A32: 练字（语） | B32: 杨彬 | C32: 史振塞 | D32: 杨彬 | E32: 史振塞 | F32: 张冰雪 | G32: 姜媛媛 | H32: 王雪莲 | I32: 路睿 | J32: 张冰雪 | K32: 王菲 | L32: 路睿 | M32: 王雪莲 | N32: 王菲 | O32: 姜媛媛 | P32: 路睿
A33: 练字（外） | B33: 岳/厉 | C33: 岳/厉 | D33: 岳/厉 | E33: 岳/厉 | F33: 王灼 | G33: 翟淑玮 | H33: 韩丽梅 | I33: 宋平 | J33: 王灼 | K33: 胡存想 | L33: 王/宋/翟/胡 | M33: 韩/宋/翟/胡 | N33: 宋/韩/王 | O33: 翟/韩/王 | P33: 胡/韩/王
A34: 语 文
A35: 外 语
A36: 生 物
A37: 政 治
A38: 历 史
A39: 地 理
A40: 活动
...

Sheet 总课表
A1: 江河高级中学2026年春季学期总课表 星 期 一 | AA1: 江河高级中学2026年春季学期总课表 星 期 二 | AY1: 江河高级中学2026年春季学期总课表 星 期 三 | BW1: 江河高级中学2026年春季学期总课表 星 期 四 | CU1: 江河高级中学2026年春季学期总课表 星 期 五 | DS1: 江河高级中学2026年春季学期总课表 星 期 六 | EQ1: 江河高级中学2026年春季学期总课表 星 期 日 | FO1: 江河高级中学2026年春季学期总课表 星 期 一 | GM1: 江河高级中学2026年春季学期总课表 星 期 二 | HK1: 江河高级中学2026年春季学期总课表 星 期 三 | II1: 江河高级中学2026年春季学期高中总课表 星 期 四 | JG1: 江河高级中学2026年春季学期总课表 星 期 五
A2: 班级 序号 | C2: 1 | D2: 2 | E2: 3 | F2: 4 | G2: 5 | H2: 6 | I2: 7 | J2: 8 | K2: 9 | L2: 10 | M2: 11 | N2: 12 | O2: 13 | P2: 14 | Q2: 15 | R2: 16 | S2: 17 | T2: 18 | U2: 19 | V2: 20 | W2: 21 | X2: 22 | Y2: 23 | Z2: 24 | AA2: 1 | AB2: 2 | AC2: 3 | AD2: 4 | AE2: 5 | AF2: 6 | AG2: 7 | AH2: 8 | AI2: 9 | AJ2: 10 | AK2: 11 | AL2: 12 | AM2: 13 | AN2: 14 | AO2: 15 | AP2: 16 | AQ2: 17 | AR2: 18 | AS2: 19 | AT2: 20 | AU2: 21 | AV2: 22 | AW2: 23 | AX2: 24 | AY2: 1 | AZ2: 2 | BA2: 3 | BB2: 4 | BC2: 5 | BD2: 6 | BE2: 7 | BF2: 8 | BG2: 9 | BH2: 10 | BI2: 11 | BJ2: 12 | BK2: 13 | BL2: 14 | BM2: 15 | BN2: 16 | BO2: 17 | BP2: 18 | BQ2: 19 | BR2: 20 | BS2: 21 | BT2: 22 | BU2: 23 | BV2: 24 | BW2: 1 | BX2: 2 | BY2: 3 | BZ2: 4 | CA2: 5 | CB2: 6 | CC2: 7 | CD2: 8 | CE2: 9 | CF2: 10 | CG2: 11 | CH2: 12 | CI2: 13 | CJ2: 14 | CK2: 15 | CL2: 16 | CM2: 17 | CN2: 18 | CO2: 19 | CP2: 20 | CQ2: 21 | CR2: 22 | CS2: 23 | CT2: 24 | CU2: 1 | CV2: 2 | CW2: 3 | CX2: 4 | CY2: 5 | CZ2: 6 | DA2: 7 | DB2: 8 | DC2: 9 | DD2: 10 | DE2: 11 | DF2: 12 | DG2: 13 | DH2: 14 | DI2: 15 | DJ2: 16 | DK2: 17 | DL2: 18 | DM2: 19 | DN2: 20 | DO2: 21 | DP2: 22 | DQ2: 23 | DR2: 24 | DS2: 1 | DT2: 2 | DU2: 3 | DV2: 4 | DW2: 5 | DX2: 6 | DY2: 7 | DZ2: 8 | EA2: 9 | EB2: 10 | EC2: 11 | ED2: 12 | EE2: 13 | EF2: 14 | EG2: 15 | EH2: 16 | EI2: 17 | EJ2: 18 | EK2: 19 | EL2: 20 | EM2: 21 | EN2: 22 | EO2: 23 | EP2: 24 | EQ2: 1 | ER2: 2 | ES2: 3 | ET2: 4 | EU2: 5 | EV2: 6 | EW2: 7 | EX2: 8 | EY2: 9 | EZ2: 10 | FA2: 11 | FB2: 12 | FC2: 13 | FD2: 14 | FE2: 15 | FF2: 16 | FG2: 17 | FH2: 18 | FI2: 19 | FJ2: 20 | FK2: 21 | FL2: 22 | FM2: 23 | FN2: 24 | FO2: 1 | FP2: 2 | FQ2: 3 | FR2: 4 | FS2: 5 | FT2: 6 | FU2: 7 | FV2: 8 | FW2: 9 | FX2: 10 | FY2: 11 | FZ2: 12 | GA2: 13 | GB2: 14 | GC2: 15 | GD2: 16 | GE2: 17 | GF2: 18 | GG2: 19 | GH2: 20 | GI2: 21 | GJ2: 22 | GK2: 23 | GL2: 24 | GM2: 1 | GN2: 2 | GO2: 3 | GP2: 4 | GQ2: 5 | GR2: 6 | GS2: 7 | GT2: 8 | GU2: 9 | GV2: 10 | GW2: 11 | GX2: 12 | GY2: 13 | GZ2: 14 | HA2: 15 | HB2: 16 | HC2: 17 | HD2: 18 | HE2: 19 | HF2: 20 | HG2: 21 | HH2: 22 | HI2: 23 | HJ2: 24 | HK2: 1 | HL2: 2 | HM2: 3 | HN2: 4 | HO2: 5 | HP2: 6 | HQ2: 7 | HR2: 8 | HS2: 9 | HT2: 10 | HU2: 11 | HV2: 12 | HW2: 13 | HX2: 14 | HY2: 15 | HZ2: 16 | IA2: 17 | IB2: 18 | IC2: 19 | ID2: 20 | IE2: 21 | IF2: 22 | IG2: 23 | IH2: 24 | II2: 1 | IJ2: 2 | IK2: 3 | IL2: 4 | IM2: 5 | IN2: 6 | IO2: 7 | IP2: 8 | IQ2: 9 | IR2: 10 | IS2: 11 | IT2: 12 | IU2: 13 | IV2: 14 | IW2: 15 | IX2: 16 | IY2: 17 | IZ2: 18 | JA2: 19 | JB2: 20 | JC2: 21 | JD2: 22 | JE2: 23 | JF2: 24 | JG2: 1 | JH2: 2 | JI2: 3 | JJ2: 4 | JK2: 5 | JL2: 6 | JM2: 7 | JN2: 8 | JO2: 9 | JP2: 10 | JQ2: 11 | JR2: 12 | JS2: 13 | JT2: 14 | JU2: 15 | JV2: 16 | JW2: 17 | JX2: 18 | JY2: 19 | JZ2: 20 | KA2: 21 | KB2: 22 | KC2: 23 | KD2: 24
A3: 班级 | C3: 101 | D3: 102 | E3: 103 | F3: 104 | G3: 201 | H3: 202 | I3: 203 | J3: 204 | K3: 205 | L3: 206 | M3: 207 | N3: 208 | O3: 209 | P3: 210 | Q3: 211 | R3: 高一英语（1）班 | S3: 高一英语（2）班 | T3: 高一俄语（1）班 | U3: 高一俄语（2）班 | V3: 高二俄语（2）班 | W3: 高二俄语（1）班 | X3: 高二英语（1）班 | Y3: 高二英语（2）班 | Z3: 高二英语（3）班 | AA3: 101 | AB3: 102 | AC3: 103 | AD3: 104 | AE3: 201 | AF3: 202 | AG3: 203 | AH3: 204 | AI3: 205 | AJ3: 206 | AK3: 207 | AL3: 208 | AM3: 209 | AN3: 210 | AO3: 211 | AP3: 高一英语（1）班 | AQ3: 高一英语（2）班 | AR3: 高一俄语（1）班 | AS3: 高一俄语（2）班 | AT3: 高二俄语（2）班 | AU3: 高二俄语（1）班 | AV3: 高二英语（1）班 | AW3: 高二英语（2）班 | AX3: 高二英语（3）班 | AY3: 101 | AZ3: 102 | BA3: 103 | BB3: 104 | BC3: 201 | BD3: 202 | BE3: 203 | BF3: 204 | BG3: 205 | BH3: 206 | BI3: 207 | BJ3: 208 | BK3: 209 | BL3: 210 | BM3: 211 | BN3: 高一英语（1）班 | BO3: 高一英语（2）班 | BP3: 高一俄语（1）班 | BQ3: 高一俄语（2）班 | BR3: 高二俄语（2）班 | BS3: 高二俄语（1）班 | BT3: 高二英语（1）班 | BU3: 高二英语（2）班 | BV3: 高二英语（3）班 | BW3: 101 | BX3: 102 | BY3: 103 | BZ3: 104 | CA3: 201 | CB3: 202 | CC3: 203 | CD3: 204 | CE3: 205 | CF3: 206 | CG3: 207 | CH3: 208 | CI3: 209 | CJ3: 210 | CK3: 211 | CL3: 高一英语（1）班 | CM3: 高一英语（2）班 | CN3: 高一俄语（1）班 | CO3: 高一俄语（2）班 | CP3: 高二俄语（2）班 | CQ3: 高二俄语（1）班 | CR3: 高二英语（1）班 | CS3: 高二英语（2）班 | CT3: 高二英语（3）班 | CU3: 101 | CV3: 102 | CW3: 103 | CX3: 104 | CY3: 201 | CZ3: 202 | DA3: 203 | DB3: 204 | DC3: 205 | DD3: 206 | DE3: 207 | DF3: 208 | DG3: 209 | DH3: 210 | DI3: 211 | DJ3: 高一英语（1）班 | DK3: 高一英语（2）班 | DL3: 高一俄语（1）班 | DM3: 高一俄语（2）班 | DN3: 高二俄语（2）班 | DO3: 高二俄语（1）班 | DP3: 高二英语（1）班 | DQ3: 高二英语（2）班 | DR3: 高二英语（3）班 | DS3: 101 | DT3: 102 | DU3: 103 | DV3: 104 | DW3: 201 | DX3: 202 | DY3: 203 | DZ3: 204 | EA3: 205 | EB3: 206 | EC3: 207 | ED3: 208 | EE3: 209 | EF3: 210 | EG3: 211 | EH3: 高一英语（1）班 | EI3: 高一英语（2）班 | EJ3: 高一俄语（1）班 | EK3: 高一俄语（2）班 | EL3: 高二俄语（2）班 | EM3: 高二俄语（1）班 | EN3: 高二英语（1）班 | EO3: 高二英语（2）班 | EP3: 高二英语（3）班 | EQ3: 101 | ER3: 102 | ES3: 103 | ET3: 104 | EU3: 201 | EV3: 202 | EW3: 203 | EX3: 204 | EY3: 205 | EZ3: 206 | FA3: 207 | FB3: 208 | FC3: 209 | FD3: 210 | FE3: 211 | FF3: 高一英语（1）班 | FG3: 高一英语（2）班 | FH3: 高一俄语（1）班 | FI3: 高一俄语（2）班 | FJ3: 高二俄语（2）班 | FK3: 高二俄语（1）班 | FL3: 高二英语（1）班 | FM3: 高二英语（2）班 | FN3: 高二英语（3）班 | FO3: 101 | FP3: 102 | FQ3: 103 | FR3: 104 | FS3: 201 | FT3: 202 | FU3: 203 | FV3: 204 | FW3: 205 | FX3: 206 | FY3: 207 | FZ3: 208 | GA3: 209 | GB3: 210 | GC3: 211 | GD3: 高一英语（1）班 | GE3: 高一英语（2）班 | GF3: 高一俄语（1）班 | GG3: 高一俄语（2）班 | GH3: 高二俄语（2）班 | GI3: 高二俄语（1）班 | GJ3: 高二英语（1）班 | GK3: 高二英语（2）班 | GL3: 高二英语（3）班 | GM3: 101 | GN3: 102 | GO3: 103 | GP3: 104 | GQ3: 201 | GR3: 202 | GS3: 203 | GT3: 204 | GU3: 205 | GV3: 206 | GW3: 207 | GX3: 208 | GY3: 209 | GZ3: 210 | HA3: 211 | HB3: 高一英语（1）班 | HC3: 高一英语（2）班 | HD3: 高一俄语（1）班 | HE3: 高一俄语（2）班 | HF3: 高二俄语（2）班 | HG3: 高二俄语（1）班 | HH3: 高二英语（1）班 | HI3: 高二英语（2）班 | HJ3: 高二英语（3）班 | HK3: 101 | HL3: 102 | HM3: 103 | HN3: 104 | HO3: 201 | HP3: 202 | HQ3: 203 | HR3: 204 | HS3: 205 | HT3: 206 | HU3: 207 | HV3: 208 | HW3: 209 | HX3: 210 | HY3: 211 | HZ3: 高一英语（1）班 | IA3: 高一英语（2）班 | IB3: 高一俄语（1）班 | IC3: 高一俄语（2）班 | ID3: 高二俄语（2）班 | IE3: 高二俄语（1）班 | IF3: 高二英语（1）班 | IG3: 高二英语（2）班 | IH3: 高二英语（3）班 | II3: 101 | IJ3: 102 | IK3: 103 | IL3: 104 | IM3: 201 | IN3: 202 | IO3: 203 | IP3: 204 | IQ3: 205 | IR3: 206 | IS3: 207 | IT3: 208 | IU3: 209 | IV3: 210 | IW3: 211 | IX3: 高一英语（1）班 | IY3: 高一英语（2）班 | IZ3: 高一俄语（1）班 | JA3: 高一俄语（2）班 | JB3: 高二俄语（2）班 | JC3: 高二俄语（1）班 | JD3: 高二英语（1）班 | JE3: 高二英语（2）班 | JF3: 高二英语（3）班 | JG3: 101 | JH3: 102 | JI3: 103 | JJ3: 104 | JK3: 201 | JL3: 202 | JM3: 203 | JN3: 204 | JO3: 205 | JP3: 206 | JQ3: 207 | JR3: 208 | JS3: 209 | JT3: 210 | JU3: 211 | JV3: 高一英语（1）班 | JW3: 高一英语（2）班 | JX3: 高一俄语（1）班 | JY3: 高一俄语（2）班 | JZ3: 高二俄语（2）班 | KA3: 高二俄语（1）班 | KB3: 高二英语（1）班 | KC3: 高二英语（2）班 | KD3: 高二英语（3）班
A4: 早上 | B4: 晨读 | C4: 语 文 | D4: 语 文 | E4: 语 文 | F4: 语 文 | G4: 语 文 | H4: 语 文 | I4: 语 文 | J4: 语 文 | K4: 语 文 | L4: 语 文 | M4: 语 文 | N4: 语 文 | O4: 语 文 | P4: 语 文 | Q4: 语 文 | AA4: 生 物 | AB4: 生 物 | AC4: 生 物 | AD4: 生 物 | AE4: 外 语 | AF4: 外 语 | AG4: 外 语 | AH4: 外 语 | AI4: 外 语 | AJ4: 外 语 | AK4: 外 语 | AL4: 外 语 | AM4: 外 语 | AN4: 外 语 | AO4: 外 语 | AY4: 外 语 | AZ4: 外 语 | BA4: 外 语 | BB4: 外 语 | BC4: 生 物 | BD4: 生 物 | BE4: 地 理 | BF4: 地 理 | BG4: 生 物 | BH4: 生 物 | BI4: 政 治 | BJ4: 政 治 | BK4: 政 治 | BL4: 政 治 | BM4: 政 治 | BW4: 语 文 | BX4: 语 文 | BY4: 语 文 | BZ4: 语 文 | CA4: 外 语 | CB4: 外 语 | CC4: 外 语 | CD4: 外 语 | CE4: 历 史 | CF4: 历 史 | CG4: 历 史 | CH4: 历 史 | CI4: 历 史 | CJ4: 历 史 | CK4: 历 史 | CU4: 政 治 | CV4: 政 治 | CW4: 政 治 | CX4: 政 治 | CY4: 语 文 | CZ4: 语 文 | DA4: 语 文 | DB4: 语 文 | DC4: 地 理 | DD4: 地 理 | DE4: 地 理 | DF4: 地 理 | DG4: 地 理 | DH4: 地 理 | DI4: 地 理 | DS4: 外 语 | DT4: 外 语 | DU4: 外 语 | DV4: 外 语 | DW4: 生 物 | DX4: 生 物 | DY4: 地 理 | DZ4: 地 理 | EA4: 外 语 | EB4: 外 语 | EC4: 外 语 | ED4: 外 语 | EE4: 外 语 | EF4: 外 语 | EG4: 外 语 | EQ4: 语 文 | ER4: 语 文 | ES4: 语 文 | ET4: 语 文 | EU4: 语 文 | EV4: 语 文 | EW4: 语 文 | EX4: 语 文 | EY4: 语 文 | EZ4: 语 文 | FA4: 语 文 | FB4: 语 文 | FC4: 语 文 | FD4: 语 文 | FE4: 语 文 | FO4: 历 史 | FP4: 历 史 | FQ4: 历 史 | FR4: 历 史 | FS4: 外 语 | FT4: 外 语 | FU4: 外 语 | FV4: 外 语 | FW4: 生 物 | FX4: 生 物 | FY4: 政 治 | FZ4: 政 治 | GA4: 政 治 | GB4: 政 治 | GC4: 政 治 | GM4: 外 语 | GN4: 外 语 | GO4: 外 语 | GP4: 外 语 | GQ4: 生 物 | GR4: 生 物 | GS4: 地 理 | GT4: 地 理 | GU4: 历 史 | GV4: 历 史 | GW4: 历 史 | GX4: 历 史 | GY4: 历 史 | GZ4: 历 史 | HA4: 历 史 | HK4: 语 文 | HL4: 语 文 | HM4: 语 文 | HN4: 语 文 | HO4: 外 语 | HP4: 外 语 | HQ4: 外 语 | HR4: 外 语 | HS4: 地 理 | HT4: 地 理 | HU4: 地 理 | HV4: 地 理 | HW4: 地 理 | HX4: 地 理 | HY4: 地 理 | II4: 地 理 | IJ4: 地 理 | IK4: 地 理 | IL4: 地 理 | IM4: 语 文 | IN4: 语 文 | IO4: 语 文 | IP4: 语 文 | IQ4: 语 文 | IR4: 语 文 | IS4: 语 文 | IT4: 语 文 | IU4: 语 文 | IV4: 语 文 | IW4: 语 文 | JG4: 外 语 | JH4: 外 语 | JI4: 外 语 | JJ4: 外 语 | JK4: 生 物 | JL4: 生 物 | JM4: 地 理 | JN4: 地 理 | JO4: 外 语 | JP4: 外 语 | JQ4: 外 语 | JR4: 外 语 | JS4: 外 语 | JT4: 外 语 | JU4: 外 语
C5: =IFERROR(VLOOKUP(C4,教师安排!$A:$Y,C$2+1,FALSE),"") -> 0 | D5: =IFERROR(VLOOKUP(D4,教师安排!$A:$Y,D$2+1,FALSE),"") -> 0 | E5: =IFERROR(VLOOKUP(E4,教师安排!$A:$Y,E$2+1,FALSE),"") -> 0 | F5: =IFERROR(VLOOKUP(F4,教师安排!$A:$Y,F$2+1,FALSE),"") -> 0 | G5: =IFERROR(VLOOKUP(G4,教师安排!$A:$Y,G$2+1,FALSE),"") -> 0 | H5: =IFERROR(VLOOKUP(H4,教师安排!$A:$Y,H$2+1,FALSE),"") -> 0 | I5: =IFERROR(VLOOKUP(I4,教师安排!$A:$Y,I$2+1,FALSE),"") -> 0 | J5: =IFERROR(VLOOKUP(J4,教师安排!$A:$Y,J$2+1,FALSE),"") -> 0 | ... U5: =IFERROR(VLOOKUP(U4,教师安排!$A:$Y,U$2+1,FALSE),"") | W5: =IFERROR(VLOOKUP(W4,教师安排!$A:$Y,W$2+1,FALSE),"") | X5: =IFERROR(VLOOKUP(X4,教师安排!$A:$Y,X$2+1,FALSE),"") | Y5: =IFERROR(VLOOKUP(Y4,教师安排!$A:$Y,Y$2+1,FALSE),"") | Z5: =IFERROR(VLOOKUP(Z4,教师安排!$A:$Y,Z$2+1,FALSE),"") | AA5: =IFERROR(VLOOKUP(AA4,教师安排!$A:$Y,AA$2+1,FALSE),"") -> 0 | AB5: =IFERROR(VLOOKUP(AB4,教师安排!$A:$Y,AB$2+1,FALSE),"") -> 0 | AC5: =IFERROR(VLOOKUP(AC4,教师安排!$A:$Y,AC$2+1,FALSE),"") -> 0 | AD5: =IFERROR(VLOOKUP(AD4,教师安排!$A:$Y,AD$2+1,FALSE),"") -> 0 | ... AS5: =IFERROR(VLOOKUP(AS4,教师安排!$A:$Y,AS$2+1,FALSE),"") | AY5: =IFERROR(VLOOKUP(AY4,教师安排!$A:$Y,AY$2+1,FALSE),"") -> 0 | AZ5: =IFERROR(VLOOKUP(AZ4,教师安排!$A:$Y,AZ$2+1,FALSE),"") -> 0 | BA5: =IFERROR(VLOOKUP(BA4,教师安排!$A:$Y,BA$2+1,FALSE),"") -> 0 | BB5: =IFERROR(VLOOKUP(BB4,教师安排!$A:$Y,BB$2+1,FALSE),"") -> 0 | BC5: =IFERROR(VLOOKUP(BC4,教师安排!$A:$Y,BC$2+1,FALSE),"") -> 0 | BD5: =IFERROR(VLOOKUP(BD4,教师安排!$A:$Y,BD$2+1,FALSE),"") -> 0 | BE5: =IFERROR(VLOOKUP(BE4,教师安排!$A:$Y,BE$2+1,FALSE),"") -> 0 | BF5: =IFERROR(VLOOKUP(BF4,教师安排!$A:$Y,BF$2+1,FALSE),"") -> 0 | ... BQ5: =IFERROR(VLOOKUP(BQ4,教师安排!$A:$Y,BQ$2+1,FALSE),"") | BS5: =IFERROR(VLOOKUP(BS4,教师安排!$A:$Y,BS$2+1,FALSE),"") | BT5: =IFERROR(VLOOKUP(BT4,教师安排!$A:$Y,BT$2+1,FALSE),"") | BU5: =IFERROR(VLOOKUP(BU4,教师安排!$A:$Y,BU$2+1,FALSE),"") | BV5: =IFERROR(VLOOKUP(BV4,教师安排!$A:$Y,BV$2+1,FALSE),"") | BW5: =IFERROR(VLOOKUP(BW4,教师安排!$A:$Y,BW$2+1,FALSE),"") -> 0 | BX5: =IFERROR(VLOOKUP(BX4,教师安排!$A:$Y,BX$2+1,FALSE),"") -> 0 | BY5: =IFERROR(VLOOKUP(BY4,教师安排!$A:$Y,BY$2+1,FALSE),"") -> 0 | BZ5: =IFERROR(VLOOKUP(BZ4,教师安排!$A:$Y,BZ$2+1,FALSE),"") -> 0 | ... CP5: =IFERROR(VLOOKUP(CP4,教师安排!$A:$Y,CP$2+1,FALSE),"") | CR5: =IFERROR(VLOOKUP(CR4,教师安排!$A:$Y,CR$2+1,FALSE),"") | CS5: =IFERROR(VLOOKUP(CS4,教师安排!$A:$Y,CS$2+1,FALSE),"") | CT5: =IFERROR(VLOOKUP(CT4,教师安排!$A:$Y,CT$2+1,FALSE),"") | CU5: =IFERROR(VLOOKUP(CU4,教师安排!$A:$Y,CU$2+1,FALSE),"") -> 0 | CV5: =IFERROR(VLOOKUP(CV4,教师安排!$A:$Y,CV$2+1,FALSE),"") -> 0 | CW5: =IFERROR(VLOOKUP(CW4,教师安排!$A:$Y,CW$2+1,FALSE),"") -> 0 | CX5: =IFERROR(VLOOKUP(CX4,教师安排!$A:$Y,CX$2+1,FALSE),"") -> 0 | CY5: =IFERROR(VLOOKUP(CY4,教师安排!$A:$Y,CY$2+1,FALSE),"") -> 0 | ... DM5: =IFERROR(VLOOKUP(DM4,教师安排!$A:$Y,DM$2+1,FALSE),"") | DO5: =IFERROR(VLOOKUP(DO4,教师安排!$A:$Y,DO$2+1,FALSE),"") | DP5: =IFERROR(VLOOKUP(DP4,教师安排!$A:$Y,DP$2+1,FALSE),"") | DQ5: =IFERROR(VLOOKUP(DQ4,教师安排!$A:$Y,DQ$2+1,FALSE),"") | DR5: =IFERROR(VLOOKUP(DR4,教师安排!$A:$Y,DR$2+1,FALSE),"") | DS5: =IFERROR(VLOOKUP(DS4,教师安排!$A:$Y,DS$2+1,FALSE),"") -> 0 | DT5: =IFERROR(VLOOKUP(DT4,教师安排!$A:$Y,DT$2+1,FALSE),"") -> 0 | DU5: =IFERROR(VLOOKUP(DU4,教师安排!$A:$Y,DU$2+1,FALSE),"") -> 0 | DV5: =IFERROR(VLOOKUP(DV4,教师安排!$A:$Y,DV$2+1,FALSE),"") -> 0 | ... EK5: =IFERROR(VLOOKUP(EK4,教师安排!$A:$Y,EK$2+1,FALSE),"") | EM5: =IFERROR(VLOOKUP(EM4,教师安排!$A:$Y,EM$2+1,FALSE),"") | EN5: =IFERROR(VLOOKUP(EN4,教师安排!$A:$Y,EN$2+1,FALSE),"") | EO5: =IFERROR(VLOOKUP(EO4,教师安排!$A:$Y,EO$2+1,FALSE),"") | EP5: =IFERROR(VLOOKUP(EP4,教师安排!$A:$Y,EP$2+1,FALSE),"") | EQ5: =IFERROR(VLOOKUP(EQ4,教师安排!$A:$Y,EQ$2+1,FALSE),"") -> 0 | ER5: =IFERROR(VLOOKUP(ER4,教师安排!$A:$Y,ER$2+1,FALSE),"") -> 0 | ES5: =IFERROR(VLOOKUP(ES4,教师安排!$A:$Y,ES$2+1,FALSE),"") -> 0 | ET5: =IFERROR(VLOOKUP(ET4,教师安排!$A:$Y,ET$2+1,FALSE),"") -> 0 | ... FI5: =IFERROR(VLOOKUP(FI4,教师安排!$A:$Y,FI$2+1,FALSE),"") | FK5: =IFERROR(VLOOKUP(FK4,教师安排!$A:$Y,FK$2+1,FALSE),"") | FL5: =IFERROR(VLOOKUP(FL4,教师安排!$A:$Y,FL$2+1,FALSE),"") | FM5: =IFERROR(VLOOKUP(FM4,教师安排!$A:$Y,FM$2+1,FALSE),"") | FN5: =IFERROR(VLOOKUP(FN4,教师安排!$A:$Y,FN$2+1,FALSE),"") | FO5: =IFERROR(VLOOKUP(FO4,教师安排!$A:$Y,FO$2+1,FALSE),"") -> 0 | FP5: =IFERROR(VLOOKUP(FP4,教师安排!$A:$Y,FP$2+1,FALSE),"") -> 0 | FQ5: =IFERROR(VLOOKUP(FQ4,教师安排!$A:$Y,FQ$2+1,FALSE),"") -> 0 | FR5: =IFERROR(VLOOKUP(FR4,教师安排!$A:$Y,FR$2+1,FALSE),"") -> 0 | ... GG5: =IFERROR(VLOOKUP(GG4,教师安排!$A:$Y,GG$2+1,FALSE),"") | GI5: =IFERROR(VLOOKUP(GI4,教师安排!$A:$Y,GI$2+1,FALSE),"") | GJ5: =IFERROR(VLOOKUP(GJ4,教师安排!$A:$Y,GJ$2+1,FALSE),"") | GK5: =IFERROR(VLOOKUP(GK4,教师安排!$A:$Y,GK$2+1,FALSE),"") | GL5: =IFERROR(VLOOKUP(GL4,教师安排!$A:$Y,GL$2+1,FALSE),"") | GM5: =IFERROR(VLOOKUP(GM4,教师安排!$A:$Y,GM$2+1,FALSE),"") -> 0 | GN5: =IFERROR(VLOOKUP(GN4,教师安排!$A:$Y,GN$2+1,FALSE),"") -> 0 | GO5: =IFERROR(VLOOKUP(GO4,教师安排!$A:$Y,GO$2+1,FALSE),"") -> 0 | GP5: =IFERROR(VLOOKUP(GP4,教师安排!$A:$Y,GP$2+1,FALSE),"") -> 0 | ... HE5: =IFERROR(VLOOKUP(HE4,教师安排!$A:$Y,HE$2+1,FALSE),"") | HG5: =IFERROR(VLOOKUP(HG4,教师安排!$A:$Y,HG$2+1,FALSE),"") | HH5: =IFERROR(VLOOKUP(HH4,教师安排!$A:$Y,HH$2+1,FALSE),"") | HI5: =IFERROR(VLOOKUP(HI4,教师安排!$A:$Y,HI$2+1,FALSE),"") | HJ5: =IFERROR(VLOOKUP(HJ4,教师安排!$A:$Y,HJ$2+1,FALSE),"") | HK5: =IFERROR(VLOOKUP(HK4,教师安排!$A:$Y,HK$2+1,FALSE),"") -> 0 | HL5: =IFERROR(VLOOKUP(HL4,教师安排!$A:$Y,HL$2+1,FALSE),"") -> 0 | HM5: =IFERROR(VLOOKUP(HM4,教师安排!$A:$Y,HM$2+1,FALSE),"") -> 0 | HN5: =IFERROR(VLOOKUP(HN4,教师安排!$A:$Y,HN$2+1,FALSE),"") -> 0 | ... IC5: =IFERROR(VLOOKUP(IC4,教师安排!$A:$Y,IC$2+1,FALSE),"") | IE5: =IFERROR(VLOOKUP(IE4,教师安排!$A:$Y,IE$2+1,FALSE),"") | IF5: =IFERROR(VLOOKUP(IF4,教师安排!$A:$Y,IF$2+1,FALSE),"") | IG5: =IFERROR(VLOOKUP(IG4,教师安排!$A:$Y,IG$2+1,FALSE),"") | IH5: =IFERROR(VLOOKUP(IH4,教师安排!$A:$Y,IH$2+1,FALSE),"") | II5: =IFERROR(VLOOKUP(II4,教师安排!$A:$Y,II$2+1,FALSE),"") -> 0 | IJ5: =IFERROR(VLOOKUP(IJ4,教师安排!$A:$Y,IJ$2+1,FALSE),"") -> 0 | IK5: =IFERROR(VLOOKUP(IK4,教师安排!$A:$Y,IK$2+1,FALSE),"") -> 0 | IL5: =IFERROR(VLOOKUP(IL4,教师安排!$A:$Y,IL$2+1,FALSE),"") -> 0 | ... JA5: =IFERROR(VLOOKUP(JA4,教师安排!$A:$Y,JA$2+1,FALSE),"") | JC5: =IFERROR(VLOOKUP(JC4,教师安排!$A:$Y,JC$2+1,FALSE),"") | JD5: =IFERROR(VLOOKUP(JD4,教师安排!$A:$Y,JD$2+1,FALSE),"") | JE5: =IFERROR(VLOOKUP(JE4,教师安排!$A:$Y,JE$2+1,FALSE),"") | JF5: =IFERROR(VLOOKUP(JF4,教师安排!$A:$Y,JF$2+1,FALSE),"") | JG5: =IFERROR(VLOOKUP(JG4,教师安排!$A:$Y,JG$2+1,FALSE),"") -> 0 | JH5: =IFERROR(VLOOKUP(JH4,教师安排!$A:$Y,JH$2+1,FALSE),"") -> 0 | JI5: =IFERROR(VLOOKUP(JI4,教师安排!$A:$Y,JI$2+1,FALSE),"") -> 0 | JJ5: =IFERROR(VLOOKUP(JJ4,教师安排!$A:$Y,JJ$2+1,FALSE),"") -> 0 | ... JY5: =IFERROR(VLOOKUP(JY4,教师安排!$A:$Y,JY$2+1,FALSE),"") | KA5: =IFERROR(VLOOKUP(KA4,教师安排!$A:$Y,KA$2+1,FALSE),"") | KB5: =IFERROR(VLOOKUP(KB4,教师安排!$A:$Y,KB$2+1,FALSE),"") | KC5: =IFERROR(VLOOKUP(KC4,教师安排!$A:$Y,KC$2+1,FALSE),"") | KD5: =IFERROR(VLOOKUP(KD4,教师安排!$A:$Y,KD$2+1,FALSE),"")
B6: 早读 | C6: 语文 | D6: 外语 | E6: 外语 | F6: 语文 | G6: 语文 | H6: 生物 | I6: 外语 | J6: 地理 | K6: 外语 | L6: 外语 | M6: 政治 | N6: 政治 | O6: 政治 | P6: 语文 | Q6: 语文 | S6: 英语 | U6: 俄语 | AA6: 外语 | AB6: 语文 | AC6: 政治 | AD6: 外语 | AE6: 生物 | AF6: 生物 | AG6: 地理 | AH6: 语文 | AI6: 历史 | AJ6: 历史 | AK6: 外语 | AL6: 外语 | AM6: 外语 | AN6: 外语 | AO6: 外语 | AP6: 英语 | AR6: 俄语 | AT6: 俄语 | AU6: 俄语 | AV6: 英语 | AW6: 英语 | AX6: 英语 | AY6: 生物 | AZ6: 语文 | BA6: 政治 | BB6: 政治 | BC6: 外语 | BD6: 外语 | BE6: 地理 | BF6: 外语 | BG6: 历史 | BH6: 语文 | BI6: 语文 | BJ6: 语文 | BK6: 政治 | BL6: 语文 | BM6: 政治 | BW6: 生物 | BX6: 政治 | BY6: 语文 | BZ6: 语文 | CA6: 生物 | CB6: 语文 | CC6: 语文 | CD6: 地理 | CE6: 语文 | CF6: 外语 | CG6: 政治 | CH6: 政治 | CI6: 语文 | CJ6: 政治 | CK6: 语文 | CU6: 外语 | CV6: 政治 | CW6: 语文 | CX6: 外语 | CY6: 语文 | CZ6: 外语 | DA6: 外语 | DB6: 语文 | DC6: 历史 | DD6: 外语 | DE6: 语文 | DF6: 语文 | DG6: 语文 | DH6: 政治 | DI6: 政治 | DJ6: 英语 | DL6: 俄语 | DS6: 生物 | DT6: 语文 | DU6: 政治 | DV6: 政治 | DW6: 外语 | DX6: 语文 | DY6: 语文 | DZ6: 外语 | EA6: 语文 | EB6: 语文 | EC6: 外语 | ED6: 外语 | EE6: 外语 | EF6: 外语 | EG6: 外语 | EL6: 俄语 | EM6: 俄语 | EN6: 英语 | EO6: 英语 | EP6: 英语 | EQ6: 语文 | ER6: 外语 | ES6: 外语 | ET6: 语文 | EU6: 生物 | EV6: 生物 | EW6: 地理 | EX6: 地理 | EY6: 外语 | EZ6: 历史 | FA6: 政治 | FB6: 政治 | FC6: 语文 | FD6: 政治 | FE6: 语文 | FG6: 英语 | FI6: 俄语 | FO6: 外语 | FP6: 政治 | FQ6: 语文 | FR6: 外语 | FS6: 语文 | FT6: 语文 | FU6: 语文 | FV6: 语文 | FW6: 外语 | FX6: 语文 | FY6: 外语 | FZ6: 外语 | GA6: 外语 | GB6: 外语 | GC6: 外语 | GD6: 英语 | GF6: 俄语 | GH6: 俄语 | GI6: 俄语 | GJ6: 英语 | GK6: 英语 | GL6: 英语 | GM6: 语文 | GN6: 外语 | GO6: 外语 | GP6: 政治 | GQ6: 外语 | GR6: 外语 | GS6: 外语 | GT6: 外语 | GU6: 语文 | GV6: 历史 | GW6: 语文 | GX6: 语文 | GY6: 政治 | GZ6: 语文 | HA6: 政治 | HC6: 英语 | HE6: 俄语 | HK6: 生物 | HL6: 政治 | HM6: 语文 | HN6: 语文 | HO6: 语文 | HP6: 语文 | HQ6: 外语 | HR6: 地理 | HS6: 外语 | HT6: 外语 | HU6: 政治 | HV6: 政治 | HW6: 语文 | HX6: 政治 | HY6: 语文 | II6: 语文 | IJ6: 外语 | IK6: 外语 | IL6: 政治 | IM6: 生物 | IN6: 生物 | IO6: 语文 | IP6: 语文 | IQ6: 历史 | IR6: 语文 | IS6: 外语 | IT6: 外语 | IU6: 外语 | IV6: 外语 | IW6: 外语 | IY6: 英语 | JA6: 俄语 | JB6: 俄语 | JC6: 俄语 | JD6: 英语 | JE6: 英语 | JF6: 英语 | JG6: 外语 | JH6: 语文 | JI6: 政治 | JJ6: 外语 | JK6: 外语 | JL6: 外语 | JM6: 地理 | JN6: 外语 | JO6: 语文 | JP6: 历史 | JQ6: 语文 | JR6: 语文 | JS6: 政治 | JT6: 语文 | JU6: 政治 | JV6: 英语 | JX6: 俄语
C7: =IFERROR(VLOOKUP(C6,教师安排!$A:$Y,C$2+1,FALSE),"") -> 杨彬 | D7: =IFERROR(VLOOKUP(D6,教师安排!$A:$Y,D$2+1,FALSE),"") -> 岳/厉 | E7: =IFERROR(VLOOKUP(E6,教师安排!$A:$Y,E$2+1,FALSE),"") -> 岳/厉 | F7: =IFERROR(VLOOKUP(F6,教师安排!$A:$Y,F$2+1,FALSE),"") -> 史振塞 | G7: =IFERROR(VLOOKUP(G6,教师安排!$A:$Y,G$2+1,FALSE),"") -> 张冰雪 | H7: =IFERROR(VLOOKUP(H6,教师安排!$A:$Y,H$2+1,FALSE),"") -> 蒋心言 | I7: =IFERROR(VLOOKUP(I6,教师安排!$A:$Y,I$2+1,FALSE),"") -> 韩丽梅 | J7: =IFERROR(VLOOKUP(J6,教师安排!$A:$Y,J$2+1,FALSE),"") -> 孙秋杰 | ... U7: =IFERROR(VLOOKUP(U6,教师安排!$A:$Y,U$2+1,FALSE),"") -> 厉彦龙 | W7: =IFERROR(VLOOKUP(W6,教师安排!$A:$Y,W$2+1,FALSE),"") | X7: =IFERROR(VLOOKUP(X6,教师安排!$A:$Y,X$2+1,FALSE),"") | Y7: =IFERROR(VLOOKUP(Y6,教师安排!$A:$Y,Y$2+1,FALSE),"") | Z7: =IFERROR(VLOOKUP(Z6,教师安排!$A:$Y,Z$2+1,FALSE),"") | AA7: =IFERROR(VLOOKUP(AA6,教师安排!$A:$Y,AA$2+1,FALSE),"") -> 岳/厉 | AB7: =IFERROR(VLOOKUP(AB6,教师安排!$A:$Y,AB$2+1,FALSE),"") -> 史振塞 | AC7: =IFERROR(VLOOKUP(AC6,教师安排!$A:$Y,AC$2+1,FALSE),"") -> 张雯皓 | AD7: =IFERROR(VLOOKUP(AD6,教师安排!$A:$Y,AD$2+1,FALSE),"") -> 岳/厉 | ... BQ7: =IFERROR(VLOOKUP(BQ6,教师安排!$A:$Y,BQ$2+1,FALSE),"") | BS7: =IFERROR(VLOOKUP(BS6,教师安排!$A:$Y,BS$2+1,FALSE),"") | BT7: =IFERROR(VLOOKUP(BT6,教师安排!$A:$Y,BT$2+1,FALSE),"") | BU7: =IFERROR(VLOOKUP(BU6,教师安排!$A:$Y,BU$2+1,FALSE),"") | BV7: =IFERROR(VLOOKUP(BV6,教师安排!$A:$Y,BV$2+1,FALSE),"") | BW7: =IFERROR(VLOOKUP(BW6,教师安排!$A:$Y,BW$2+1,FALSE),"") -> 周兴玲 | BX7: =IFERROR(VLOOKUP(BX6,教师安排!$A:$Y,BX$2+1,FALSE),"") -> 刘珊珊 | BY7: =IFERROR(VLOOKUP(BY6,教师安排!$A:$Y,BY$2+1,FALSE),"") -> 杨彬 | BZ7: =IFERROR(VLOOKUP(BZ6,教师安排!$A:$Y,BZ$2+1,FALSE),"") -> 史振塞 | ... CN7: =IFERROR(VLOOKUP(CN6,教师安排!$A:$Y,CN$2+1,FALSE),"") | CU7: =IFERROR(VLOOKUP(CU6,教师安排!$A:$Y,CU$2+1,FALSE),"") -> 岳/厉 | CV7: =IFERROR(VLOOKUP(CV6,教师安排!$A:$Y,CV$2+1,FALSE),"") -> 刘珊珊 | CW7: =IFERROR(VLOOKUP(CW6,教师安排!$A:$Y,CW$2+1,FALSE),"") -> 杨彬 | CX7: =IFERROR(VLOOKUP(CX6,教师安排!$A:$Y,CX$2+1,FALSE),"") -> 岳/厉 | CY7: =IFERROR(VLOOKUP(CY6,教师安排!$A:$Y,CY$2+1,FALSE),"") -> 张冰雪 | CZ7: =IFERROR(VLOOKUP(CZ6,教师安排!$A:$Y,CZ$2+1,FALSE),"") -> 翟淑玮 | DA7: =IFERROR(VLOOKUP(DA6,教师安排!$A:$Y,DA$2+1,FALSE),"") -> 韩丽梅 | DB7: 康波 | DC7: =IFERROR(VLOOKUP(DC6,教师安排!$A:$Y,DC$2+1,FALSE),"") -> 田凤美 | DD7: =IFERROR(VLOOKUP(DD6,教师安排!$A:$Y,DD$2+1,FALSE),"") -> 胡存想 | DE7: =IFERROR(VLOOKUP(DE6,教师安排!$A:$Y,DE$2+1,FALSE),"") -> 路睿 | DF7: =IFERROR(VLOOKUP(DF6,教师安排!$A:$Y,DF$2+1,FALSE),"") -> 王雪莲 | DG7: =IFERROR(VLOOKUP(DG6,教师安排!$A:$Y,DG$2+1,FALSE),"") -> 王菲 | DH7: =IFERROR(VLOOKUP(DH6,教师安排!$A:$Y,DH$2+1,FALSE),"") -> 李浩然 | DI7: =IFERROR(VLOOKUP(DI6,教师安排!$A:$Y,DI$2+1,FALSE),"") -> 张鑫 | DJ7: =IFERROR(VLOOKUP(DJ6,教师安排!$A:$Y,DJ$2+1,FALSE),"") -> 岳海霞 | ... DM7: =IFERROR(VLOOKUP(DM6,教师安排!$A:$Y,DM$2+1,FALSE),"") | DO7: =IFERROR(VLOOKUP(DO6,教师安排!$A:$Y,DO$2+1,FALSE),"") | DP7: =IFERROR(VLOOKUP(DP6,教师安排!$A:$Y,DP$2+1,FALSE),"") | DQ7: =IFERROR(VLOOKUP(DQ6,教师安排!$A:$Y,DQ$2+1,FALSE),"") | DR7: =IFERROR(VLOOKUP(DR6,教师安排!$A:$Y,DR$2+1,FALSE),"") | DS7: =IFERROR(VLOOKUP(DS6,教师安排!$A:$Y,DS$2+1,FALSE),"") -> 周兴玲 | DT7: =IFERROR(VLOOKUP(DT6,教师安排!$A:$Y,DT$2+1,FALSE),"") -> 史振塞 | DU7: =IFERROR(VLOOKUP(DU6,教师安排!$A:$Y,DU$2+1,FALSE),"") -> 张雯皓 | DV7: =IFERROR(VLOOKUP(DV6,教师安排!$A:$Y,DV$2+1,FALSE),"") -> 刘珊珊 | DW7: 李振铎 | DX7: =IFERROR(VLOOKUP(DX6,教师安排!$A:$Y,DX$2+1,FALSE),"") -> 姜媛媛 | DY7: =IFERROR(VLOOKUP(DY6,教师安排!$A:$Y,DY$2+1,FALSE),"") -> 王雪莲 | DZ7: 高文凤 | EA7: =IFERROR(VLOOKUP(EA6,教师安排!$A:$Y,EA$2+1,FALSE),"") -> 张冰雪 | EB7: 孙娜 | EC7: =IFERROR(VLOOKUP(EC6,教师安排!$A:$Y,EC$2+1,FALSE),"") -> 王/宋/翟/胡 | ED7: =IFERROR(VLOOKUP(ED6,教师安排!$A:$Y,ED$2+1,FALSE),"") -> 韩/宋/翟/胡 | EE7: =IFERROR(VLOOKUP(EE6,教师安排!$A:$Y,EE$2+1,FALSE),"") -> 宋/韩/王 | EF7: =IFERROR(VLOOKUP(EF6,教师安排!$A:$Y,EF$2+1,FALSE),"") -> 翟/韩/王 | EG7: =IFERROR(VLOOKUP(EG6,教师安排!$A:$Y,EG$2+1,FALSE),"") -> 胡/韩/王 | EH7: =IFERROR(VLOOKUP(EH6,教师安排!$A:$Y,EH$2+1,FALSE),"") | EI7: =IFERROR(VLOOKUP(EI6,教师安排!$A:$Y,EI$2+1,FALSE),"") | EJ7: =IFERROR(VLOOKUP(EJ6,教师安排!$A:$Y,EJ$2+1,FALSE),"") | ... FI7: =IFERROR(VLOOKUP(FI6,教师安排!$A:$Y,FI$2+1,FALSE),"") -> 厉彦龙 | FK7: =IFERROR(VLOOKUP(FK6,教师安排!$A:$Y,FK$2+1,FALSE),"") | FL7: =IFERROR(VLOOKUP(FL6,教师安排!$A:$Y,FL$2+1,FALSE),"") | FM7: =IFERROR(VLOOKUP(FM6,教师安排!$A:$Y,FM$2+1,FALSE),"") | FN7: =IFERROR(VLOOKUP(FN6,教师安排!$A:$Y,FN$2+1,FALSE),"") | FO7: =IFERROR(VLOOKUP(FO6,教师安排!$A:$Y,FO$2+1,FALSE),"") -> 岳/厉 | FP7: =IFERROR(VLOOKUP(FP6,教师安排!$A:$Y,FP$2+1,FALSE),"") -> 刘珊珊 | FQ7: =IFERROR(VLOOKUP(FQ6,教师安排!$A:$Y,FQ$2+1,FALSE),"") -> 杨彬 | FR7: =IFERROR(VLOOKUP(FR6,教师安排!$A:$Y,FR$2+1,FALSE),"") -> 岳/厉 | ... FV7: =IFERROR(VLOOKUP(FV6,教师安排!$A:$Y,FV$2+1,FALSE),"") -> 路睿 | FW7: 孙娜 | FX7: =IFERROR(VLOOKUP(FX6,教师安排!$A:$Y,FX$2+1,FALSE),"") -> 王菲 | FY7: =IFERROR(VLOOKUP(FY6,教师安排!$A:$Y,FY$2+1,FALSE),"") -> 王/宋/翟/胡 | FZ7: =IFERROR(VLOOKUP(FZ6,教师安排!$A:$Y,FZ$2+1,FALSE),"") -> 韩/宋/翟/胡 | GA7: =IFERROR(VLOOKUP(GA6,教师安排!$A:$Y,GA$2+1,FALSE),"") -> 宋/韩/王 | GB7: =IFERROR(VLOOKUP(GB6,教师安排!$A:$Y,GB$2+1,FALSE),"") -> 翟/韩/王 | GC7: =IFERROR(VLOOKUP(GC6,教师安排!$A:$Y,GC$2+1,FALSE),"") -> 胡/韩/王 | GD7: =IFERROR(VLOOKUP(GD6,教师安排!$A:$Y,GD$2+1,FALSE),"") -> 岳海霞 | GE7: =IFERROR(VLOOKUP(GE6,教师安排!$A:$Y,GE$2+1,FALSE),"") | ... HE7: =IFERROR(VLOOKUP(HE6,教师安排!$A:$Y,HE$2+1,FALSE),"") -> 厉彦龙 | HG7: =IFERROR(VLOOKUP(HG6,教师安排!$A:$Y,HG$2+1,FALSE),"") | HH7: =IFERROR(VLOOKUP(HH6,教师安排!$A:$Y,HH$2+1,FALSE),"") | HI7: =IFERROR(VLOOKUP(HI6,教师安排!$A:$Y,HI$2+1,FALSE),"") | HJ7: =IFERROR(VLOOKUP(HJ6,教师安排!$A:$Y,HJ$2+1,FALSE),"") | HK7: =IFERROR(VLOOKUP(HK6,教师安排!$A:$Y,HK$2+1,FALSE),"") -> 周兴玲 | HL7: =IFERROR(VLOOKUP(HL6,教师安排!$A:$Y,HL$2+1,FALSE),"") -> 刘珊珊 | HM7: =IFERROR(VLOOKUP(HM6,教师安排!$A:$Y,HM$2+1,FALSE),"") -> 杨彬 | HN7: =IFERROR(VLOOKUP(HN6,教师安排!$A:$Y,HN$2+1,FALSE),"") -> 史振塞 | ... IC7: =IFERROR(VLOOKUP(IC6,教师安排!$A:$Y,IC$2+1,FALSE),"") | IE7: =IFERROR(VLOOKUP(IE6,教师安排!$A:$Y,IE$2+1,FALSE),"") | IF7: =IFERROR(VLOOKUP(IF6,教师安排!$A:$Y,IF$2+1,FALSE),"") | IG7: =IFERROR(VLOOKUP(IG6,教师安排!$A:$Y,IG$2+1,FALSE),"") | IH7: =IFERROR(VLOOKUP(IH6,教师安排!$A:$Y,IH$2+1,FALSE),"") | II7: =IFERROR(VLOOKUP(II6,教师安排!$A:$Y,II$2+1,FALSE),"") -> 杨彬 | IJ7: =IFERROR(VLOOKUP(IJ6,教师安排!$A:$Y,IJ$2+1,FALSE),"") -> 岳/厉 | IK7: =IFERROR(VLOOKUP(IK6,教师安排!$A:$Y,IK$2+1,FALSE),"") -> 岳/厉 | IL7: =IFERROR(VLOOKUP(IL6,教师安排!$A:$Y,IL$2+1,FALSE),"") -> 刘珊珊 | ... JY7: =IFERROR(VLOOKUP(JY6,教师安排!$A:$Y,JY$2+1,FALSE),"") | KA7: =IFERROR(VLOOKUP(KA6,教师安排!$A:$Y,KA$2+1,FALSE),"") | KB7: =IFERROR(VLOOKUP(KB6,教师安排!$A:$Y,KB$2+1,FALSE),"") | KC7: =IFERROR(VLOOKUP(KC6,教师安排!$A:$Y,KC$2+1,FALSE),"") | KD7: =IFERROR(VLOOKUP(KD6,教师安排!$A:$Y,KD$2+1,FALSE),"")
A8: 上 午 | B8: 1 | C8: 体育 | D8: 政治 | E8: 历史 | F8: 生物 | G8: 化学 | H8: 体育 | I8: 外语 | J8: 外语 | K8: 生物 | L8: 通用 | M8: 历史 | N8: 数学 | O8: 地理 | P8: 历史 | Q8: 政治 | AA8: 化学 | AB8: 语文 | AC8: 体育 | AD8: 音乐 | AE8: 体育 | AF8: 物理 | AG8: 地理 | AH8: 语文 | AI8: 历史 | AJ8: 通用 | AK8: 外语 | AL8: 外语 | AM8: 外语 | AN8: 外语 | AO8: 外语 | AT8: 俄语 | AU8: 俄语 | AV8: 英语 | AW8: 英语 | AX8: 英语 | AY8: 美术 | AZ8: 历史 | BA8: 数学 | BB8: 数学 | BC8: 生物 | BD8: 化学 | BE8: 物理 | BF8: 地理 | BG8: 地理 | BH8: 语文 | BI8: 信息 | BJ8: 政治 | BK8: 数学 | BL8: 体育 | BM8: 语文 | BW8: 政治 | BX8: 语文 | BY8: 政治 | BZ8: 数学 | CA8: 数学 | CB8: 化学 | CC8: 语文 | CD8: 数学 | CE8: 语文 | CF8: 语文 | CG8: 外语 | CH8: 外语 | CI8: 外语 | CJ8: 外语 | CK8: 外语 | CP8: 俄语 | CQ8: 俄语 | CR8: 英语 | CS8: 英语 | CT8: 英语 | CU8: 化学 | CV8: 语文 | CW8: 地理 | CX8: 生物 | CY8: 物理 | CZ8: 生物 | DA8: 语文 | DB8: 语文 | DC8: 外语 | DD8: 外语 | DE8: 地理 | DF8: 通用 | DG8: 体育 | DH8: 体育 | DI8: 地理 | DS8: 数学 | DT8: 数学 | DU8: 生物 | DV8: 化学 | DW8: 物理 | DX8: 语文 | DY8: 外语 | DZ8: 数学 | EA8: 数学 | EB8: 外语 | EC8: 数学 | ED8: 语文 | EE8: 历史 | EF8: 地理 | EG8: 地理 | EQ8: 语文 | ER8: 地理 | ES8: 物理 | ET8: 语文 | EU8: 物理 | EV8: 生物 | EW8: 地理 | EX8: 地理 | EY8: 地理 | EZ8: 历史 | FA8: 外语 | FB8: 外语 | FC8: 外语 | FD8: 外语 | FE8: 外语 | FJ8: 俄语 | FK8: 俄语 | FL8: 英语 | FM8: 英语 | FN8: 英语 | FO8: 体育 | FP8: 政治 | FQ8: 历史 | FR8: 生物 | FS8: 化学 | FT8: 体育 | FU8: 外语 | FV8: 外语 | FW8: 生物 | FX8: 通用 | FY8: 历史 | FZ8: 数学 | GA8: 地理 | GB8: 历史 | GC8: 政治 | GM8: 化学 | GN8: 语文 | GO8: 体育 | GP8: 音乐 | GQ8: 体育 | GR8: 物理 | GS8: 地理 | GT8: 语文 | GU8: 历史 | GV8: 通用 | GW8: 外语 | GX8: 外语 | GY8: 外语 | GZ8: 外语 | HA8: 外语 | HF8: 俄语 | HG8: 俄语 | HH8: 英语 | HI8: 英语 | HJ8: 英语 | HK8: 政治 | HL8: 历史 | HM8: 数学 | HN8: 数学 | HO8: 生物 | HP8: 化学 | HQ8: 物理 | HR8: 地理 | HS8: 地理 | HT8: 语文 | HU8: 信息 | HV8: 政治 | HW8: 数学 | HX8: 体育 | HY8: 语文 | II8: 政治 | IJ8: 生物 | IK8: 政治 | IL8: 数学 | IM8: 数学 | IN8: 化学 | IO8: 语文 | IP8: 数学 | IQ8: 语文 | IR8: 语文 | IS8: 外语 | IT8: 外语 | IU8: 外语 | IV8: 外语 | IW8: 外语 | JB8: 俄语 | JC8: 俄语 | JD8: 英语 | JE8: 英语 | JF8: 英语 | JG8: 化学 | JH8: 语文 | JI8: 数学 | JJ8: 地理 | JK8: 物理 | JL8: 生物 | JM8: 语文 | JN8: 语文 | JO8: 外语 | JP8: 外语 | JQ8: 通用 | JR8: 政治 | JS8: 体育 | JT8: 体育 | JU8: 地理
C9: =IFERROR(VLOOKUP(C8,教师安排!$A:$Y,C$2+1,FALSE),"") -> 王庆超 | D9: =IFERROR(VLOOKUP(D8,教师安排!$A:$Y,D$2+1,FALSE),"") -> 刘珊珊 | E9: =IFERROR(VLOOKUP(E8,教师安排!$A:$Y,E$2+1,FALSE),"") -> 李雯 | F9: =IFERROR(VLOOKUP(F8,教师安排!$A:$Y,F$2+1,FALSE),"") -> 周兴玲 | G9: =IFERROR(VLOOKUP(G8,教师安排!$A:$Y,G$2+1,FALSE),"") -> 李振铎 | H9: =IFERROR(VLOOKUP(H8,教师安排!$A:$Y,H$2+1,FALSE),"") -> 刘天骄 | I9: =IFERROR(VLOOKUP(I8,教师安排!$A:$Y,I$2+1,FALSE),"") -> 韩丽梅 | J9: =IFERROR(VLOOKUP(J8,教师安排!$A:$Y,J$2+1,FALSE),"") -> 宋平 | ... U9: =IFERROR(VLOOKUP(U8,教师安排!$A:$Y,U$2+1,FALSE),"") | W9: =IFERROR(VLOOKUP(W8,教师安排!$A:$Y,W$2+1,FALSE),"") | X9: =IFERROR(VLOOKUP(X8,教师安排!$A:$Y,X$2+1,FALSE),"") | Y9: =IFERROR(VLOOKUP(Y8,教师安排!$A:$Y,Y$2+1,FALSE),"") | Z9: =IFERROR(VLOOKUP(Z8,教师安排!$A:$Y,Z$2+1,FALSE),"") | AA9: =IFERROR(VLOOKUP(AA8,教师安排!$A:$Y,AA$2+1,FALSE),"") -> 马崇庆 | AB9: =IFERROR(VLOOKUP(AB8,教师安排!$A:$Y,AB$2+1,FALSE),"") -> 史振塞 | AC9: =IFERROR(VLOOKUP(AC8,教师安排!$A:$Y,AC$2+1,FALSE),"") -> 王庆超 | AD9: =IFERROR(VLOOKUP(AD8,教师安排!$A:$Y,AD$2+1,FALSE),"") -> 李冰慧 | ... BQ9: =IFERROR(VLOOKUP(BQ8,教师安排!$A:$Y,BQ$2+1,FALSE),"") | BS9: =IFERROR(VLOOKUP(BS8,教师安排!$A:$Y,BS$2+1,FALSE),"") | BT9: =IFERROR(VLOOKUP(BT8,教师安排!$A:$Y,BT$2+1,FALSE),"") | BU9: =IFERROR(VLOOKUP(BU8,教师安排!$A:$Y,BU$2+1,FALSE),"") | BV9: =IFERROR(VLOOKUP(BV8,教师安排!$A:$Y,BV$2+1,FALSE),"") | BW9: =IFERROR(VLOOKUP(BW8,教师安排!$A:$Y,BW$2+1,FALSE),"") -> 刘珊珊 | BX9: =IFERROR(VLOOKUP(BX8,教师安排!$A:$Y,BX$2+1,FALSE),"") -> 史振塞 | BY9: =IFERROR(VLOOKUP(BY8,教师安排!$A:$Y,BY$2+1,FALSE),"") -> 张雯皓 | BZ9: =IFERROR(VLOOKUP(BZ8,教师安排!$A:$Y,BZ$2+1,FALSE),"") -> 侯淑贤 | ... DM9: =IFERROR(VLOOKUP(DM8,教师安排!$A:$Y,DM$2+1,FALSE),"") | DO9: =IFERROR(VLOOKUP(DO8,教师安排!$A:$Y,DO$2+1,FALSE),"") | DP9: =IFERROR(VLOOKUP(DP8,教师安排!$A:$Y,DP$2+1,FALSE),"") | DQ9: =IFERROR(VLOOKUP(DQ8,教师安排!$A:$Y,DQ$2+1,FALSE),"") | DR9: =IFERROR(VLOOKUP(DR8,教师安排!$A:$Y,DR$2+1,FALSE),"") | DS9: =IFERROR(VLOOKUP(DS8,教师安排!$A:$Y,DS$2+1,FALSE),"") -> 侯淑贤 | DT9: =IFERROR(VLOOKUP(DT8,教师安排!$A:$Y,DT$2+1,FALSE),"") -> 姚来朋 | DU9: =IFERROR(VLOOKUP(DU8,教师安排!$A:$Y,DU$2+1,FALSE),"") -> 周兴玲 | DV9: =IFERROR(VLOOKUP(DV8,教师安排!$A:$Y,DV$2+1,FALSE),"") -> 马崇庆 | ... EK9: =IFERROR(VLOOKUP(EK8,教师安排!$A:$Y,EK$2+1,FALSE),"") | EM9: =IFERROR(VLOOKUP(EM8,教师安排!$A:$Y,EM$2+1,FALSE),"") | EN9: =IFERROR(VLOOKUP(EN8,教师安排!$A:$Y,EN$2+1,FALSE),"") | EO9: =IFERROR(VLOOKUP(EO8,教师安排!$A:$Y,EO$2+1,FALSE),"") | EP9: =IFERROR(VLOOKUP(EP8,教师安排!$A:$Y,EP$2+1,FALSE),"") | EQ9: =IFERROR(VLOOKUP(EQ8,教师安排!$A:$Y,EQ$2+1,FALSE),"") -> 杨彬 | ER9: =IFERROR(VLOOKUP(ER8,教师安排!$A:$Y,ER$2+1,FALSE),"") -> 李会玲 | ES9: =IFERROR(VLOOKUP(ES8,教师安排!$A:$Y,ES$2+1,FALSE),"") -> 张雨晴 | ET9: =IFERROR(VLOOKUP(ET8,教师安排!$A:$Y,ET$2+1,FALSE),"") -> 史振塞 | ... GG9: =IFERROR(VLOOKUP(GG8,教师安排!$A:$Y,GG$2+1,FALSE),"") | GI9: =IFERROR(VLOOKUP(GI8,教师安排!$A:$Y,GI$2+1,FALSE),"") | GJ9: =IFERROR(VLOOKUP(GJ8,教师安排!$A:$Y,GJ$2+1,FALSE),"") | GK9: =IFERROR(VLOOKUP(GK8,教师安排!$A:$Y,GK$2+1,FALSE),"") | GL9: =IFERROR(VLOOKUP(GL8,教师安排!$A:$Y,GL$2+1,FALSE),"") | GM9: =IFERROR(VLOOKUP(GM8,教师安排!$A:$Y,GM$2+1,FALSE),"") -> 马崇庆 | GN9: =IFERROR(VLOOKUP(GN8,教师安排!$A:$Y,GN$2+1,FALSE),"") -> 史振塞 | GO9: =IFERROR(VLOOKUP(GO8,教师安排!$A:$Y,GO$2+1,FALSE),"") -> 王庆超 | GP9: =IFERROR(VLOOKUP(GP8,教师安排!$A:$Y,GP$2+1,FALSE),"") -> 李冰慧 | ... IC9: =IFERROR(VLOOKUP(IC8,教师安排!$A:$Y,IC$2+1,FALSE),"") | IE9: =IFERROR(VLOOKUP(IE8,教师安排!$A:$Y,IE$2+1,FALSE),"") | IF9: =IFERROR(VLOOKUP(IF8,教师安排!$A:$Y,IF$2+1,FALSE),"") | IG9: =IFERROR(VLOOKUP(IG8,教师安排!$A:$Y,IG$2+1,FALSE),"") | IH9: =IFERROR(VLOOKUP(IH8,教师安排!$A:$Y,IH$2+1,FALSE),"") | II9: =IFERROR(VLOOKUP(II8,教师安排!$A:$Y,II$2+1,FALSE),"") -> 刘珊珊 | IJ9: =IFERROR(VLOOKUP(IJ8,教师安排!$A:$Y,IJ$2+1,FALSE),"") -> 周兴玲 | IK9: =IFERROR(VLOOKUP(IK8,教师安排!$A:$Y,IK$2+1,FALSE),"") -> 张雯皓 | IL9: =IFERROR(VLOOKUP(IL8,教师安排!$A:$Y,IL$2+1,FALSE),"") -> 侯淑贤 | ... JY9: =IFERROR(VLOOKUP(JY8,教师安排!$A:$Y,JY$2+1,FALSE),"") | KA9: =IFERROR(VLOOKUP(KA8,教师安排!$A:$Y,KA$2+1,FALSE),"") | KB9: =IFERROR(VLOOKUP(KB8,教师安排!$A:$Y,KB$2+1,FALSE),"") | KC9: =IFERROR(VLOOKUP(KC8,教师安排!$A:$Y,KC$2+1,FALSE),"") | KD9: =IFERROR(VLOOKUP(KD8,教师安排!$A:$Y,KD$2+1,FALSE),"")
B10: 2 | C10: 音乐 | D10: 历史 | E10: 体育 | F10: 信息 | G10: 体育 | H10: 化学 | I10: 物理 | J10: 化学 | K10: 数学 | L10: 历史 | M10: 外语 | N10: 外语 | O10: 外语 | P10: 外语 | Q10: 外语 | V10: 俄语 | W10: 俄语 | X10: 英语 | Y10: 英语 | Z10: 英语 | AA10: 生物 | AB10: 体育 | AC10: 语文 | AD10: 政治 | AE10: 生物 | AF10: 化学 | AG10: 化学 | AH10: 信息 | AI10: 地理 | AJ10: 体育 | AK10: 外语 | AL10: 外语 | AM10: 外语 | AN10: 外语 | AO10: 外语 | AT10: 俄语 | AU10: 俄语 | AV10: 英语 | AW10: 英语 | AX10: 英语 | AY10: 数学 | AZ10: 物理 | BA10: 政治 | BB10: 语文 | BC10: 物理 | BD10: 体育 | BE10: 语文 | BF10: 物理 | BG10: 体育 | BH10: 历史 | BI10: 历史 | BJ10: 通用 | BK10: 语文 | BL10: 地理 | BM10: 地理 | BW10: 化学 | BX10: 音乐 | BY10: 政治 | BZ10: 政治 | CA10: 物理 | CB10: 数学 | CC10: 数学 | CD10: 语文 | CE10: 数学 | CF10: 生物 | CG10: 外语 | CH10: 外语 | CI10: 外语 | CJ10: 外语 | CK10: 外语 | CP10: 俄语 | CQ10: 俄语 | CR10: 英语 | CS10: 英语 | CT10: 英语 | CU10: 体育 | CV10: 历史 | CW10: 数学 | CX10: 地理 | CY10: 物理 | CZ10: 语文 | DA10: 体育 | DB10: 体育 | DC10: 信息 | DD10: 生物 | DE10: 外语 | DF10: 外语 | DG10: 外语 | DH10: 外语 | DI10: 外语 | DN10: 俄语 | DO10: 俄语 | DP10: 英语 | DQ10: 英语 | DR10: 英语 | DS10: 数学 | DT10: 数学 | DU10: 化学 | DV10: 生物 | DW10: 物理 | DX10: 化学 | DY10: 外语 | DZ10: 数学 | EA10: 数学 | EB10: 外语 | EC10: 数学 | ED10: 语文 | EE10: 历史 | EF10: 语文 | EG10: 地理 | EQ10: 物理 | ER10: 物理 | ES10: 语文 | ET10: 地理 | EU10: 生物 | EV10: 物理 | EW10: 化学 | EX10: 地理 | EY10: 地理 | EZ10: 历史 | FA10: 外语 | FB10: 外语 | FC10: 外语 | FD10: 外语 | FE10: 外语 | FJ10: 俄语 | FK10: 俄语 | FL10: 英语 | FM10: 英语 | FN10: 英语 | FO10: 音乐 | FP10: 历史 | FQ10: 体育 | FR10: 信息 | FS10: 体育 | FT10: 化学 | FU10: 物理 | FV10: 化学 | FW10: 数学 | FX10: 历史 | FY10: 外语 | FZ10: 外语 | GA10: 外语 | GB10: 外语 | GC10: 外语 | GH10: 俄语 | GI10: 俄语 | GJ10: 英语 | GK10: 英语 | GL10: 英语 | GM10: 政治 | GN10: 体育 | GO10: 语文 | GP10: 物理 | GQ10: 生物 | GR10: 化学 | GS10: 化学 | GT10: 信息 | GU10: 地理 | GV10: 体育 | GW10: 外语 | GX10: 外语 | GY10: 外语 | GZ10: 外语 | HA10: 外语 | HF10: 俄语 | HG10: 俄语 | HH10: 英语 | HI10: 英语 | HJ10: 英语 | HK10: 数学 | HL10: 物理 | HM10: 政治 | HN10: 语文 | HO10: 物理 | HP10: 体育 | HQ10: 语文 | HR10: 物理 | HS10: 体育 | HT10: 历史 | HU10: 历史 | HV10: 通用 | HW10: 语文 | HX10: 地理 | HY10: 地理 | II10: 化学 | IJ10: 音乐 | IK10: 政治 | IL10: 地理 | IM10: 物理 | IN10: 数学 | IO10: 数学 | IP10: 语文 | IQ10: 地理 | IR10: 生物 | IS10: 外语 | IT10: 外语 | IU10: 外语 | IV10: 外语 | IW10: 外语 | JB10: 俄语 | JC10: 俄语 | JD10: 英语 | JE10: 英语 | JF10: 英语 | JG10: 体育 | JH10: 历史 | JI10: 地理 | JJ10: 化学 | JK10: 物理 | JL10: 语文 | JM10: 体育 | JN10: 地理 | JO10: 信息 | JP10: 体育 | JQ10: 外语 | JR10: 外语 | JS10: 外语 | JT10: 外语 | JU10: 外语 | JZ10: 俄语 | KA10: 俄语 | KB10: 英语 | KC10: 英语 | KD10: 英语
C11: =IFERROR(VLOOKUP(C10,教师安排!$A:$Y,C$2+1,FALSE),"") -> 李冰慧 | D11: =IFERROR(VLOOKUP(D10,教师安排!$A:$Y,D$2+1,FALSE),"") -> 田凤美 | E11: =IFERROR(VLOOKUP(E10,教师安排!$A:$Y,E$2+1,FALSE),"") -> 王庆超 | F11: =IFERROR(VLOOKUP(F10,教师安排!$A:$Y,F$2+1,FALSE),"") -> 张喆 | G11: =IFERROR(VLOOKUP(G10,教师安排!$A:$Y,G$2+1,FALSE),"") -> 袁奇 | H11: =IFERROR(VLOOKUP(H10,教师安排!$A:$Y,H$2+1,FALSE),"") -> 李振铎 | I11: =IFERROR(VLOOKUP(I10,教师安排!$A:$Y,I$2+1,FALSE),"") -> 孙存义 | J11: =IFERROR(VLOOKUP(J10,教师安排!$A:$Y,J$2+1,FALSE),"") -> 宋开元 | ... EK11: =IFERROR(VLOOKUP(EK10,教师安排!$A:$Y,EK$2+1,FALSE),"") | EM11: =IFERROR(VLOOKUP(EM10,教师安排!$A:$Y,EM$2+1,FALSE),"") | EN11: =IFERROR(VLOOKUP(EN10,教师安排!$A:$Y,EN$2+1,FALSE),"") | EO11: =IFERROR(VLOOKUP(EO10,教师安排!$A:$Y,EO$2+1,FALSE),"") | EP11: =IFERROR(VLOOKUP(EP10,教师安排!$A:$Y,EP$2+1,FALSE),"") | EQ11: =IFERROR(VLOOKUP(EQ10,教师安排!$A:$Y,EQ$2+1,FALSE),"") -> 康波 | ER11: =IFERROR(VLOOKUP(ER10,教师安排!$A:$Y,ER$2+1,FALSE),"") -> 张雨晴 | ES11: =IFERROR(VLOOKUP(ES10,教师安排!$A:$Y,ES$2+1,FALSE),"") -> 杨彬 | ET11: =IFERROR(VLOOKUP(ET10,教师安排!$A:$Y,ET$2+1,FALSE),"") -> 李会玲 | ... KD11: =IFERROR(VLOOKUP(KD10,教师安排!$A:$Y,KD$2+1,FALSE),"") -> 胡存想
B12: 大课间
DS13: =IFERROR(VLOOKUP(DS12,教师安排!$A:$Y,DS$2+1,FALSE),"") | DT13: =IFERROR(VLOOKUP(DT12,教师安排!$A:$Y,DT$2+1,FALSE),"") | DU13: =IFERROR(VLOOKUP(DU12,教师安排!$A:$Y,DU$2+1,FALSE),"") | DV13: =IFERROR(VLOOKUP(DV12,教师安排!$A:$Y,DV$2+1,FALSE),"") | DW13: =IFERROR(VLOOKUP(DW12,教师安排!$A:$Y,DW$2+1,FALSE),"") | DX13: =IFERROR(VLOOKUP(DX12,教师安排!$A:$Y,DX$2+1,FALSE),"") | DY13: =IFERROR(VLOOKUP(DY12,教师安排!$A:$Y,DY$2+1,FALSE),"") | DZ13: =IFERROR(VLOOKUP(DZ12,教师安排!$A:$Y,DZ$2+1,FALSE),"") | ... EG13: =IFERROR(VLOOKUP(EG12,教师安排!$A:$Y,EG$2+1,FALSE),"") | FO13: =IFERROR(VLOOKUP(FO12,教师安排!$A:$Y,FO$2+1,FALSE),"") | FP13: =IFERROR(VLOOKUP(FP12,教师安排!$A:$Y,FP$2+1,FALSE),"") | FQ13: =IFERROR(VLOOKUP(FQ12,教师安排!$A:$Y,FQ$2+1,FALSE),"") | FR13: =IFERROR(VLOOKUP(FR12,教师安排!$A:$Y,FR$2+1,FALSE),"") | FS13: =IFERROR(VLOOKUP(FS12,教师安排!$A:$Y,FS$2+1,FALSE),"") | FT13: =IFERROR(VLOOKUP(FT12,教师安排!$A:$Y,FT$2+1,FALSE),"") | FU13: =IFERROR(VLOOKUP(FU12,教师安排!$A:$Y,FU$2+1,FALSE),"") | FV13: =IFERROR(VLOOKUP(FV12,教师安排!$A:$Y,FV$2+1,FALSE),"") | ... GC13: =IFERROR(VLOOKUP(GC12,教师安排!$A:$Y,GC$2+1,FALSE),"") | HK13: =IFERROR(VLOOKUP(HK12,教师安排!$A:$Y,HK$2+1,FALSE),"") | HL13: =IFERROR(VLOOKUP(HL12,教师安排!$A:$Y,HL$2+1,FALSE),"") | HM13: =IFERROR(VLOOKUP(HM12,教师安排!$A:$Y,HM$2+1,FALSE),"") | HN13: =IFERROR(VLOOKUP(HN12,教师安排!$A:$Y,HN$2+1,FALSE),"") | HO13: =IFERROR(VLOOKUP(HO12,教师安排!$A:$Y,HO$2+1,FALSE),"") | HP13: =IFERROR(VLOOKUP(HP12,教师安排!$A:$Y,HP$2+1,FALSE),"") | HQ13: =IFERROR(VLOOKUP(HQ12,教师安排!$A:$Y,HQ$2+1,FALSE),"") | HR13: =IFERROR(VLOOKUP(HR12,教师安排!$A:$Y,HR$2+1,FALSE),"") | ... HY13: =IFERROR(VLOOKUP(HY12,教师安排!$A:$Y,HY$2+1,FALSE),"")
B14: 3 | C14: 历史 | D14: 生物 | E14: 化学 | F14: 班会 | G14: 通用 | H14: 物理 | I14: 化学 | J14: 物理 | K14: 历史 | L14: 生物 | M14: 班会 | N14: 地理 | O14: 数学 | P14: 数学 | Q14: 地理 | AA14: 外语 | AB14: 信息 | AC14: 语文 | AD14: 外语 | AE14: 化学 | AF14: 外语 | AG14: 外语 | AH14: 物理 | AI14: 地理 | AJ14: 地理 | AK14: 通用 | AL14: 历史 | AM14: 历史 | AN14: 语文 | AO14: 语文 | AP14: 英语 | AR14: 俄语 | AY14: 信息 | AZ14: 政治 | BA14: 语文 | BB14: 物理 | BC14: 语文 | BD14: 语文 | BE14: 语文 | BF14: 语文 | BG14: 数学 | BH14: 语文 | BI14: 数学 | BJ14: 地理 | BK14: 信息 | BL14: 数学 | BM14: 数学 | BW14: 外语 | BX14: 数学 | BY14: 物理 | BZ14: 外语 | CA14: 语文 | CB14: 语文 | CC14: 数学 | CD14: 化学 | CE14: 外语 | CF14: 外语 | CG14: 历史 | CH14: 信息 | CI14: 语文 | CJ14: 数学 | CK14: 政治 | CL14: 英语 | CN14: 俄语 | CU14: 物理 | CV14: 生物 | CW14: 音乐 | CX14: 政治 | CY14: 外语 | CZ14: 外语 | DA14: 数学 | DB14: 外语 | DC14: 数学 | DD14: 生物 | DE14: 通用 | DF14: 政治 | DG14: 政治 | DH14: 数学 | DI14: 历史 | DS14: 历史 | DT14: 生物 | DU14: 政治 | DV14: 数学 | DW14: 数学 | DX14: 外语 | DY14: 数学 | DZ14: 化学 | EA14: 历史 | EB14: 地理 | EC14: 地理 | ED14: 数学 | EE14: 语文 | EF14: 数学 | EG14: 历史 | EQ14: 化学 | ER14: 语文 | ES14: 地理 | ET14: 物理 | EU14: 外语 | EV14: 外语 | EW14: 数学 | EX14: 外语 | EY14: 生物 | EZ14: 生物 | FA14: 地理 | FB14: 地理 | FC14: 历史 | FD14: 政治 | FE14: 政治 | FO14: 历史 | FP14: 生物 | FQ14: 化学 | FR14: 班会 | FS14: 通用 | FT14: 物理 | FU14: 化学 | FV14: 物理 | FW14: 历史 | FX14: 生物 | FY14: 班会 | FZ14: 地理 | GA14: 数学 | GB14: 数学 | GC14: 地理 | GM14: 外语 | GN14: 信息 | GO14: 语文 | GP14: 外语 | GQ14: 化学 | GR14: 外语 | GS14: 外语 | GT14: 物理 | GU14: 地理 | GV14: 地理 | GW14: 通用 | GX14: 历史 | GY14: 历史 | GZ14: 语文 | HA14: 政治 | HB14: 英语 | HD14: 俄语 | HK14: 信息 | HL14: 政治 | HM14: 语文 | HN14: 物理 | HO14: 语文 | HP14: 语文 | HQ14: 语文 | HR14: 语文 | HS14: 数学 | HT14: 语文 | HU14: 数学 | HV14: 地理 | HW14: 信息 | HX14: 数学 | HY14: 数学 | II14: 外语 | IJ14: 数学 | IK14: 物理 | IL14: 外语 | IM14: 语文 | IN14: 语文 | IO14: 数学 | IP14: 化学 | IQ14: 外语 | IR14: 外语 | IS14: 历史 | IT14: 信息 | IU14: 语文 | IV14: 数学 | IW14: 政治 | IX14: 英语 | IZ14: 俄语 | JG14: 物理 | JH14: 物理 | JI14: 音乐 | JJ14: 政治 | JK14: 外语 | JL14: 外语 | JM14: 数学 | JN14: 外语 | JO14: 数学 | JP14: 生物 | JQ14: 地理 | JR14: 通用 | JS14: 政治 | JT14: 数学 | JU14: 历史
C15: =IFERROR(VLOOKUP(C14,教师安排!$A:$Y,C$2+1,FALSE),"") -> 李雯 | D15: =IFERROR(VLOOKUP(D14,教师安排!$A:$Y,D$2+1,FALSE),"") -> 周兴玲 | E15: =IFERROR(VLOOKUP(E14,教师安排!$A:$Y,E$2+1,FALSE),"") -> 宋开元 | F15: =IFERROR(VLOOKUP(F14,教师安排!$A:$Y,F$2+1,FALSE),"") -> 王庆超 | G15: =IFERROR(VLOOKUP(G14,教师安排!$A:$Y,G$2+1,FALSE),"") -> 孙显阳 | H15: =IFERROR(VLOOKUP(H14,教师安排!$A:$Y,H$2+1,FALSE),"") -> 孙存义 | I15: =IFERROR(VLOOKUP(I14,教师安排!$A:$Y,I$2+1,FALSE),"") -> 马崇庆 | J15: =IFERROR(VLOOKUP(J14,教师安排!$A:$Y,J$2+1,FALSE),"") -> 康波 | ... U15: =IFERROR(VLOOKUP(U14,教师安排!$A:$Y,U$2+1,FALSE),"") | W15: =IFERROR(VLOOKUP(W14,教师安排!$A:$Y,W$2+1,FALSE),"") | X15: =IFERROR(VLOOKUP(X14,教师安排!$A:$Y,X$2+1,FALSE),"") | Y15: =IFERROR(VLOOKUP(Y14,教师安排!$A:$Y,Y$2+1,FALSE),"") | Z15: =IFERROR(VLOOKUP(Z14,教师安排!$A:$Y,Z$2+1,FALSE),"") | AA15: =IFERROR(VLOOKUP(AA14,教师安排!$A:$Y,AA$2+1,FALSE),"") -> 岳/厉 | AB15: =IFERROR(VLOOKUP(AB14,教师安排!$A:$Y,AB$2+1,FALSE),"") -> 张喆 | AC15: =IFERROR(VLOOKUP(AC14,教师安排!$A:$Y,AC$2+1,FALSE),"") -> 杨彬 | AD15: =IFERROR(VLOOKUP(AD14,教师安排!$A:$Y,AD$2+1,FALSE),"") -> 岳/厉 | ... AS15: =IFERROR(VLOOKUP(AS14,教师安排!$A:$Y,AS$2+1,FALSE),"") | AU15: =IFERROR(VLOOKUP(AU14,教师安排!$A:$Y,AU$2+1,FALSE),"") | AV15: =IFERROR(VLOOKUP(AV14,教师安排!$A:$Y,AV$2+1,FALSE),"") | AW15: =IFERROR(VLOOKUP(AW14,教师安排!$A:$Y,AW$2+1,FALSE),"") | AX15: =IFERROR(VLOOKUP(AX14,教师安排!$A:$Y,AX$2+1,FALSE),"") | AY15: =IFERROR(VLOOKUP(AY14,教师安排!$A:$Y,AY$2+1,FALSE),"") -> 张喆 | AZ15: =IFERROR(VLOOKUP(AZ14,教师安排!$A:$Y,AZ$2+1,FALSE),"") -> 刘珊珊 | BA15: =IFERROR(VLOOKUP(BA14,教师安排!$A:$Y,BA$2+1,FALSE),"") -> 杨彬 | BB15: =IFERROR(VLOOKUP(BB14,教师安排!$A:$Y,BB$2+1,FALSE),"") -> 康波 | ... BQ15: =IFERROR(VLOOKUP(BQ14,教师安排!$A:$Y,BQ$2+1,FALSE),"") | BS15: =IFERROR(VLOOKUP(BS14,教师安排!$A:$Y,BS$2+1,FALSE),"") | BT15: =IFERROR(VLOOKUP(BT14,教师安排!$A:$Y,BT$2+1,FALSE),"") | BU15: =IFERROR(VLOOKUP(BU14,教师安排!$A:$Y,BU$2+1,FALSE),"") | BV15: =IFERROR(VLOOKUP(BV14,教师安排!$A:$Y,BV$2+1,FALSE),"") | BW15: =IFERROR(VLOOKUP(BW14,教师安排!$A:$Y,BW$2+1,FALSE),"") -> 岳/厉 | BX15: =IFERROR(VLOOKUP(BX14,教师安排!$A:$Y,BX$2+1,FALSE),"") -> 姚来朋 | BY15: =IFERROR(VLOOKUP(BY14,教师安排!$A:$Y,BY$2+1,FALSE),"") -> 张雨晴 | BZ15: =IFERROR(VLOOKUP(BZ14,教师安排!$A:$Y,BZ$2+1,FALSE),"") -> 岳/厉 | ... CP15: =IFERROR(VLOOKUP(CP14,教师安排!$A:$Y,CP$2+1,FALSE),"") | CR15: =IFERROR(VLOOKUP(CR14,教师安排!$A:$Y,CR$2+1,FALSE),"") | CS15: =IFERROR(VLOOKUP(CS14,教师安排!$A:$Y,CS$2+1,FALSE),"") | CT15: =IFERROR(VLOOKUP(CT14,教师安排!$A:$Y,CT$2+1,FALSE),"") | CU15: =IFERROR(VLOOKUP(CU14,教师安排!$A:$Y,CU$2+1,FALSE),"") -> 康波 | CV15: =IFERROR(VLOOKUP(CV14,教师安排!$A:$Y,CV$2+1,FALSE),"") -> 周兴玲 | CW15: =IFERROR(VLOOKUP(CW14,教师安排!$A:$Y,CW$2+1,FALSE),"") -> 李冰慧 | CX15: =IFERROR(VLOOKUP(CX14,教师安排!$A:$Y,CX$2+1,FALSE),"") -> 刘珊珊 | CY15: =IFERROR(VLOOKUP(CY14,教师安排!$A:$Y,CY$2+1,FALSE),"") -> 王灼 | ... DM15: =IFERROR(VLOOKUP(DM14,教师安排!$A:$Y,DM$2+1,FALSE),"") | DO15: =IFERROR(VLOOKUP(DO14,教师安排!$A:$Y,DO$2+1,FALSE),"") | DP15: =IFERROR(VLOOKUP(DP14,教师安排!$A:$Y,DP$2+1,FALSE),"") | DQ15: =IFERROR(VLOOKUP(DQ14,教师安排!$A:$Y,DQ$2+1,FALSE),"") | DR15: =IFERROR(VLOOKUP(DR14,教师安排!$A:$Y,DR$2+1,FALSE),"") | DS15: =IFERROR(VLOOKUP(DS14,教师安排!$A:$Y,DS$2+1,FALSE),"") -> 李雯 | DT15: =IFERROR(VLOOKUP(DT14,教师安排!$A:$Y,DT$2+1,FALSE),"") -> 周兴玲 | DU15: =IFERROR(VLOOKUP(DU14,教师安排!$A:$Y,DU$2+1,FALSE),"") -> 张雯皓 | DV15: =IFERROR(VLOOKUP(DV14,教师安排!$A:$Y,DV$2+1,FALSE),"") -> 侯淑贤 | ... EK15: =IFERROR(VLOOKUP(EK14,教师安排!$A:$Y,EK$2+1,FALSE),"") | EM15: =IFERROR(VLOOKUP(EM14,教师安排!$A:$Y,EM$2+1,FALSE),"") | EN15: =IFERROR(VLOOKUP(EN14,教师安排!$A:$Y,EN$2+1,FALSE),"") | EO15: =IFERROR(VLOOKUP(EO14,教师安排!$A:$Y,EO$2+1,FALSE),"") | EP15: =IFERROR(VLOOKUP(EP14,教师安排!$A:$Y,EP$2+1,FALSE),"") | EQ15: =IFERROR(VLOOKUP(EQ14,教师安排!$A:$Y,EQ$2+1,FALSE),"") -> 马崇庆 | ER15: =IFERROR(VLOOKUP(ER14,教师安排!$A:$Y,ER$2+1,FALSE),"") -> 史振塞 | ES15: =IFERROR(VLOOKUP(ES14,教师安排!$A:$Y,ES$2+1,FALSE),"") -> 李会玲 | ET15: =IFERROR(VLOOKUP(ET14,教师安排!$A:$Y,ET$2+1,FALSE),"") -> 康波 | ... FI15: =IFERROR(VLOOKUP(FI14,教师安排!$A:$Y,FI$2+1,FALSE),"") | FK15: =IFERROR(VLOOKUP(FK14,教师安排!$A:$Y,FK$2+1,FALSE),"") | FL15: =IFERROR(VLOOKUP(FL14,教师安排!$A:$Y,FL$2+1,FALSE),"") | FM15: =IFERROR(VLOOKUP(FM14,教师安排!$A:$Y,FM$2+1,FALSE),"") | FN15: =IFERROR(VLOOKUP(FN14,教师安排!$A:$Y,FN$2+1,FALSE),"") | FO15: =IFERROR(VLOOKUP(FO14,教师安排!$A:$Y,FO$2+1,FALSE),"") -> 李雯 | FP15: =IFERROR(VLOOKUP(FP14,教师安排!$A:$Y,FP$2+1,FALSE),"") -> 周兴玲 | FQ15: =IFERROR(VLOOKUP(FQ14,教师安排!$A:$Y,FQ$2+1,FALSE),"") -> 宋开元 | FR15: =IFERROR(VLOOKUP(FR14,教师安排!$A:$Y,FR$2+1,FALSE),"") -> 王庆超 | ... GG15: =IFERROR(VLOOKUP(GG14,教师安排!$A:$Y,GG$2+1,FALSE),"") | GI15: =IFERROR(VLOOKUP(GI14,教师安排!$A:$Y,GI$2+1,FALSE),"") | GJ15: =IFERROR(VLOOKUP(GJ14,教师安排!$A:$Y,GJ$2+1,FALSE),"") | GK15: =IFERROR(VLOOKUP(GK14,教师安排!$A:$Y,GK$2+1,FALSE),"") | GL15: =IFERROR(VLOOKUP(GL14,教师安排!$A:$Y,GL$2+1,FALSE),"") | GM15: =IFERROR(VLOOKUP(GM14,教师安排!$A:$Y,GM$2+1,FALSE),"") -> 岳/厉 | GN15: =IFERROR(VLOOKUP(GN14,教师安排!$A:$Y,GN$2+1,FALSE),"") -> 张喆 | GO15: =IFERROR(VLOOKUP(GO14,教师安排!$A:$Y,GO$2+1,FALSE),"") -> 杨彬 | GP15: =IFERROR(VLOOKUP(GP14,教师安排!$A:$Y,GP$2+1,FALSE),"") -> 岳/厉 | ... HE15: =IFERROR(VLOOKUP(HE14,教师安排!$A:$Y,HE$2+1,FALSE),"") | HG15: =IFERROR(VLOOKUP(HG14,教师安排!$A:$Y,HG$2+1,FALSE),"") | HH15: =IFERROR(VLOOKUP(HH14,教师安排!$A:$Y,HH$2+1,FALSE),"") | HI15: =IFERROR(VLOOKUP(HI14,教师安排!$A:$Y,HI$2+1,FALSE),"") | HJ15: =IFERROR(VLOOKUP(HJ14,教师安排!$A:$Y,HJ$2+1,FALSE),"") | HK15: =IFERROR(VLOOKUP(HK14,教师安排!$A:$Y,HK$2+1,FALSE),"") -> 张喆 | HL15: =IFERROR(VLOOKUP(HL14,教师安排!$A:$Y,HL$2+1,FALSE),"") -> 刘珊珊 | HM15: =IFERROR(VLOOKUP(HM14,教师安排!$A:$Y,HM$2+1,FALSE),"") -> 杨彬 | HN15: =IFERROR(VLOOKUP(HN14,教师安排!$A:$Y,HN$2+1,FALSE),"") -> 康波 | ... IC15: =IFERROR(VLOOKUP(IC14,教师安排!$A:$Y,IC$2+1,FALSE),"") | IE15: =IFERROR(VLOOKUP(IE14,教师安排!$A:$Y,IE$2+1,FALSE),"") | IF15: =IFERROR(VLOOKUP(IF14,教师安排!$A:$Y,IF$2+1,FALSE),"") | IG15: =IFERROR(VLOOKUP(IG14,教师安排!$A:$Y,IG$2+1,FALSE),"") | IH15: =IFERROR(VLOOKUP(IH14,教师安排!$A:$Y,IH$2+1,FALSE),"") | II15: =IFERROR(VLOOKUP(II14,教师安排!$A:$Y,II$2+1,FALSE),"") -> 岳/厉 | IJ15: =IFERROR(VLOOKUP(IJ14,教师安排!$A:$Y,IJ$2+1,FALSE),"") -> 姚来朋 | IK15: =IFERROR(VLOOKUP(IK14,教师安排!$A:$Y,IK$2+1,FALSE),"") -> 张雨晴 | IL15: =IFERROR(VLOOKUP(IL14,教师安排!$A:$Y,IL$2+1,FALSE),"") -> 岳/厉 | ... JA15: =IFERROR(VLOOKUP(JA14,教师安排!$A:$Y,JA$2+1,FALSE),"") | JC15: =IFERROR(VLOOKUP(JC14,教师安排!$A:$Y,JC$2+1,FALSE),"") | JD15: =IFERROR(VLOOKUP(JD14,教师安排!$A:$Y,JD$2+1,FALSE),"") | JE15: =IFERROR(VLOOKUP(JE14,教师安排!$A:$Y,JE$2+1,FALSE),"") | JF15: =IFERROR(VLOOKUP(JF14,教师安排!$A:$Y,JF$2+1,FALSE),"") | JG15: =IFERROR(VLOOKUP(JG14,教师安排!$A:$Y,JG$2+1,FALSE),"") -> 康波 | JH15: =IFERROR(VLOOKUP(JH14,教师安排!$A:$Y,JH$2+1,FALSE),"") -> 张雨晴 | JI15: =IFERROR(VLOOKUP(JI14,教师安排!$A:$Y,JI$2+1,FALSE),"") -> 李冰慧 | JJ15: =IFERROR(VLOOKUP(JJ14,教师安排!$A:$Y,JJ$2+1,FALSE),"") -> 刘珊珊 | ... JY15: =IFERROR(VLOOKUP(JY14,教师安排!$A:$Y,JY$2+1,FALSE),"") | KA15: =IFERROR(VLOOKUP(KA14,教师安排!$A:$Y,KA$2+1,FALSE),"") | KB15: =IFERROR(VLOOKUP(KB14,教师安排!$A:$Y,KB$2+1,FALSE),"") | KC15: =IFERROR(VLOOKUP(KC14,教师安排!$A:$Y,KC$2+1,FALSE),"") | KD15: =IFERROR(VLOOKUP(KD14,教师安排!$A:$Y,KD$2+1,FALSE),"")
B16: 4 | C16: 政治 | D16: 语文 | E16: 政治 | F16: 数学 | G16: 物理 | H16: 数学 | I16: 地理 | J16: 物理 | K16: 语文 | L16: 语文 | M16: 体育训练 | N16: 历史 | O16: 政治 | P16: 语文 | Q16: 历史 | AA16: 外语 | AB16: 美术 | AC16: 地理 | AD16: 外语 | AE16: 数学 | AF16: 数学 | AG16: 语文 | AH16: 物理 | AI16: 外语 | AJ16: 数学 | AK16: 体育训练 | AL16: 信息 | AM16: 地理 | AN16: 语文 | AO16: 历史 | AP16: 英语 | AR16: 俄语 | AY16: 物理 | AZ16: 生物 | BA16: 信息 | BB16: 政治 | BC16: 语文 | BD16: 通用 | BE16: 数学 | BF16: 地理 | BG16: 数学 | BH16: 生物 | BI16: 体育训练 | BJ16: 数学 | BK16: 政治 | BL16: 数学 | BM16: 政治 | BW16: 数学 | BX16: 外语 | BY16: 外语 | BZ16: 物理 | CA16: 生物 | CB16: 生物 | CC16: 物理 | CD16: 化学 | CE16: 外语 | CF16: 外语 | CG16: 体育训练 | CH16: 语文 | CI16: 历史 | CJ16: 语文 | CK16: 语文 | CM16: 英语 | CO16: 俄语 | CU16: 外语 | CV16: 地理 | CW16: 生物 | CX16: 外语 | CY16: 数学 | CZ16: 数学 | DA16: 物理 | DB16: 信息 | DC16: 生物 | DD16: 地理 | DE16: 体育训练 | DF16: 历史 | DG16: 信息 | DH16: 语文 | DI16: 语文 | DJ16: 英语 | DL16: 俄语 | DS16: 历史 | DT16: 化学 | DU16: 数学 | DV16: 数学 | DW16: 化学 | DX16: 物理 | DY16: 语文 | DZ16: 地理 | EA16: 历史 | EB16: 语文 | EC16: 政治 | ED16: 数学 | EE16: 数学 | EF16: 数学 | EG16: 数学 | EQ16: 外语 | ER16: 语文 | ES16: 地理 | ET16: 外语 | EU16: 外语 | EV16: 生物 | EW16: 数学 | EX16: 物理 | EY16: 生物 | EZ16: 地理 | FA16: 地理 | FB16: 政治 | FC16: 政治 | FD16: 历史 | FE16: 历史 | FF16: 英语 | FH16: 俄语 | FO16: 地理 | FP16: 语文 | FQ16: 政治 | FR16: 数学 | FS16: 物理 | FT16: 数学 | FU16: 地理 | FV16: 物理 | FW16: 语文 | FX16: 语文 | FY16: 体育训练 | FZ16: 历史 | GA16: 政治 | GB16: 语文 | GC16: 历史 | GM16: 生物 | GN16: 化学 | GO16: 物理 | GP16: 政治 | GQ16: 数学 | GR16: 数学 | GS16: 语文 | GT16: 物理 | GU16: 外语 | GV16: 数学 | GW16: 体育训练 | GX16: 信息 | GY16: 地理 | GZ16: 语文 | HA16: 历史 | HK16: 物理 | HL16: 语文 | HM16: 信息 | HN16: 政治 | HO16: 语文 | HP16: 通用 | HQ16: 数学 | HR16: 地理 | HS16: 数学 | HT16: 生物 | HU16: 体育训练 | HV16: 数学 | HW16: 政治 | HX16: 数学 | HY16: 语文 | II16: 数学 | IJ16: 外语 | IK16: 外语 | IL16: 物理 | IM16: 生物 | IN16: 生物 | IO16: 物理 | IP16: 化学 | IQ16: 外语 | IR16: 外语 | IS16: 体育训练 | IT16: 政治 | IU16: 历史 | IV16: 语文 | IW16: 语文 | IY16: 英语 | JA16: 俄语 | JG16: 外语 | JH16: 地理 | JI16: 物理 | JJ16: 外语 | JK16: 数学 | JL16: 数学 | JM16: 物理 | JN16: 信息 | JO16: 生物 | JP16: 地理 | JQ16: 体育训练 | JR16: 历史 | JS16: 信息 | JT16: 语文 | JU16: 语文 | JV16: 英语 | JX16: 俄语
C17: =IFERROR(VLOOKUP(C16,教师安排!$A:$Y,C$2+1,FALSE),"") -> 刘珊珊 | D17: =IFERROR(VLOOKUP(D16,教师安排!$A:$Y,D$2+1,FALSE),"") -> 史振塞 | E17: =IFERROR(VLOOKUP(E16,教师安排!$A:$Y,E$2+1,FALSE),"") -> 张雯皓 | F17: =IFERROR(VLOOKUP(F16,教师安排!$A:$Y,F$2+1,FALSE),"") -> 侯淑贤 | G17: =IFERROR(VLOOKUP(G16,教师安排!$A:$Y,G$2+1,FALSE),"") -> 孙存义 | H17: =IFERROR(VLOOKUP(H16,教师安排!$A:$Y,H$2+1,FALSE),"") -> 王露 | I17: =IFERROR(VLOOKUP(I16,教师安排!$A:$Y,I$2+1,FALSE),"") -> 孙锦锦 | J17: =IFERROR(VLOOKUP(J16,教师安排!$A:$Y,J$2+1,FALSE),"") -> 康波 | ... U17: =IFERROR(VLOOKUP(U16,教师安排!$A:$Y,U$2+1,FALSE),"") | W17: =IFERROR(VLOOKUP(W16,教师安排!$A:$Y,W$2+1,FALSE),"") | X17: =IFERROR(VLOOKUP(X16,教师安排!$A:$Y,X$2+1,FALSE),"") | Y17: =IFERROR(VLOOKUP(Y16,教师安排!$A:$Y,Y$2+1,FALSE),"") | Z17: =IFERROR(VLOOKUP(Z16,教师安排!$A:$Y,Z$2+1,FALSE),"") | AA17: =IFERROR(VLOOKUP(AA16,教师安排!$A:$Y,AA$2+1,FALSE),"") -> 岳/厉 | AB17: =IFERROR(VLOOKUP(AB16,教师安排!$A:$Y,AB$2+1,FALSE),"") -> 张苏 | AC17: =IFERROR(VLOOKUP(AC16,教师安排!$A:$Y,AC$2+1,FALSE),"") -> 李会玲 | AD17: =IFERROR(VLOOKUP(AD16,教师安排!$A:$Y,AD$2+1,FALSE),"") -> 岳/厉 | ... AS17: =IFERROR(VLOOKUP(AS16,教师安排!$A:$Y,AS$2+1,FALSE),"") | AU17: =IFERROR(VLOOKUP(AU16,教师安排!$A:$Y,AU$2+1,FALSE),"") | AV17: =IFERROR(VLOOKUP(AV16,教师安排!$A:$Y,AV$2+1,FALSE),"") | AW17: =IFERROR(VLOOKUP(AW16,教师安排!$A:$Y,AW$2+1,FALSE),"") | AX17: =IFERROR(VLOOKUP(AX16,教师安排!$A:$Y,AX$2+1,FALSE),"") | AY17: =IFERROR(VLOOKUP(AY16,教师安排!$A:$Y,AY$2+1,FALSE),"") -> 康波 | AZ17: =IFERROR(VLOOKUP(AZ16,教师安排!$A:$Y,AZ$2+1,FALSE),"") -> 周兴玲 | BA17: =IFERROR(VLOOKUP(BA16,教师安排!$A:$Y,BA$2+1,FALSE),"") -> 张喆 | BB17: =IFERROR(VLOOKUP(BB16,教师安排!$A:$Y,BB$2+1,FALSE),"") -> 刘珊珊 | ... BQ17: =IFERROR(VLOOKUP(BQ16,教师安排!$A:$Y,BQ$2+1,FALSE),"") | BS17: =IFERROR(VLOOKUP(BS16,教师安排!$A:$Y,BS$2+1,FALSE),"") | BT17: =IFERROR(VLOOKUP(BT16,教师安排!$A:$Y,BT$2+1,FALSE),"") | BU17: =IFERROR(VLOOKUP(BU16,教师安排!$A:$Y,BU$2+1,FALSE),"") | BV17: =IFERROR(VLOOKUP(BV16,教师安排!$A:$Y,BV$2+1,FALSE),"") | BW17: =IFERROR(VLOOKUP(BW16,教师安排!$A:$Y,BW$2+1,FALSE),"") -> 侯淑贤 | BX17: =IFERROR(VLOOKUP(BX16,教师安排!$A:$Y,BX$2+1,FALSE),"") -> 岳/厉 | BY17: =IFERROR(VLOOKUP(BY16,教师安排!$A:$Y,BY$2+1,FALSE),"") -> 岳/厉 | BZ17: =IFERROR(VLOOKUP(BZ16,教师安排!$A:$Y,BZ$2+1,FALSE),"") -> 康波 | ... CP17: =IFERROR(VLOOKUP(CP16,教师安排!$A:$Y,CP$2+1,FALSE),"") | CR17: =IFERROR(VLOOKUP(CR16,教师安排!$A:$Y,CR$2+1,FALSE),"") | CS17: =IFERROR(VLOOKUP(CS16,教师安排!$A:$Y,CS$2+1,FALSE),"") | CT17: =IFERROR(VLOOKUP(CT16,教师安排!$A:$Y,CT$2+1,FALSE),"") | CU17: =IFERROR(VLOOKUP(CU16,教师安排!$A:$Y,CU$2+1,FALSE),"") -> 岳/厉 | CV17: =IFERROR(VLOOKUP(CV16,教师安排!$A:$Y,CV$2+1,FALSE),"") -> 李会玲 | CW17: =IFERROR(VLOOKUP(CW16,教师安排!$A:$Y,CW$2+1,FALSE),"") -> 周兴玲 | CX17: =IFERROR(VLOOKUP(CX16,教师安排!$A:$Y,CX$2+1,FALSE),"") -> 岳/厉 | CY17: =IFERROR(VLOOKUP(CY16,教师安排!$A:$Y,CY$2+1,FALSE),"") -> 赵雪敏 | ... DM17: =IFERROR(VLOOKUP(DM16,教师安排!$A:$Y,DM$2+1,FALSE),"") | DO17: =IFERROR(VLOOKUP(DO16,教师安排!$A:$Y,DO$2+1,FALSE),"") | DP17: =IFERROR(VLOOKUP(DP16,教师安排!$A:$Y,DP$2+1,FALSE),"") | DQ17: =IFERROR(VLOOKUP(DQ16,教师安排!$A:$Y,DQ$2+1,FALSE),"") | DR17: =IFERROR(VLOOKUP(DR16,教师安排!$A:$Y,DR$2+1,FALSE),"") | DS17: =IFERROR(VLOOKUP(DS16,教师安排!$A:$Y,DS$2+1,FALSE),"") -> 李雯 | DT17: =IFERROR(VLOOKUP(DT16,教师安排!$A:$Y,DT$2+1,FALSE),"") -> 宋开元 | DU17: =IFERROR(VLOOKUP(DU16,教师安排!$A:$Y,DU$2+1,FALSE),"") -> 姚来朋 | DV17: =IFERROR(VLOOKUP(DV16,教师安排!$A:$Y,DV$2+1,FALSE),"") -> 侯淑贤 | ... EK17: =IFERROR(VLOOKUP(EK16,教师安排!$A:$Y,EK$2+1,FALSE),"") | EM17: =IFERROR(VLOOKUP(EM16,教师安排!$A:$Y,EM$2+1,FALSE),"") | EN17: =IFERROR(VLOOKUP(EN16,教师安排!$A:$Y,EN$2+1,FALSE),"") | EO17: =IFERROR(VLOOKUP(EO16,教师安排!$A:$Y,EO$2+1,FALSE),"") | EP17: =IFERROR(VLOOKUP(EP16,教师安排!$A:$Y,EP$2+1,FALSE),"") | EQ17: =IFERROR(VLOOKUP(EQ16,教师安排!$A:$Y,EQ$2+1,FALSE),"") -> 岳/厉 | ER17: =IFERROR(VLOOKUP(ER16,教师安排!$A:$Y,ER$2+1,FALSE),"") -> 史振塞 | ES17: =IFERROR(VLOOKUP(ES16,教师安排!$A:$Y,ES$2+1,FALSE),"") -> 李会玲 | ET17: =IFERROR(VLOOKUP(ET16,教师安排!$A:$Y,ET$2+1,FALSE),"") -> 岳/厉 | ... FI17: =IFERROR(VLOOKUP(FI16,教师安排!$A:$Y,FI$2+1,FALSE),"") | FK17: =IFERROR(VLOOKUP(FK16,教师安排!$A:$Y,FK$2+1,FALSE),"") | FL17: =IFERROR(VLOOKUP(FL16,教师安排!$A:$Y,FL$2+1,FALSE),"") | FM17: =IFERROR(VLOOKUP(FM16,教师安排!$A:$Y,FM$2+1,FALSE),"") | FN17: =IFERROR(VLOOKUP(FN16,教师安排!$A:$Y,FN$2+1,FALSE),"") | FO17: =IFERROR(VLOOKUP(FO16,教师安排!$A:$Y,FO$2+1,FALSE),"") -> 李会玲 | FP17: =IFERROR(VLOOKUP(FP16,教师安排!$A:$Y,FP$2+1,FALSE),"") -> 史振塞 | FQ17: =IFERROR(VLOOKUP(FQ16,教师安排!$A:$Y,FQ$2+1,FALSE),"") -> 张雯皓 | FR17: =IFERROR(VLOOKUP(FR16,教师安排!$A:$Y,FR$2+1,FALSE),"") -> 侯淑贤 | ... GG17: =IFERROR(VLOOKUP(GG16,教师安排!$A:$Y,GG$2+1,FALSE),"") | GI17: =IFERROR(VLOOKUP(GI16,教师安排!$A:$Y,GI$2+1,FALSE),"") | GJ17: =IFERROR(VLOOKUP(GJ16,教师安排!$A:$Y,GJ$2+1,FALSE),"") | GK17: =IFERROR(VLOOKUP(GK16,教师安排!$A:$Y,GK$2+1,FALSE),"") | GL17: =IFERROR(VLOOKUP(GL16,教师安排!$A:$Y,GL$2+1,FALSE),"") | GM17: =IFERROR(VLOOKUP(GM16,教师安排!$A:$Y,GM$2+1,FALSE),"") -> 周兴玲 | GN17: =IFERROR(VLOOKUP(GN16,教师安排!$A:$Y,GN$2+1,FALSE),"") -> 宋开元 | GO17: =IFERROR(VLOOKUP(GO16,教师安排!$A:$Y,GO$2+1,FALSE),"") -> 张雨晴 | GP17: =IFERROR(VLOOKUP(GP16,教师安排!$A:$Y,GP$2+1,FALSE),"") -> 刘珊珊 | ... HE17: =IFERROR(VLOOKUP(HE16,教师安排!$A:$Y,HE$2+1,FALSE),"") | HG17: =IFERROR(VLOOKUP(HG16,教师安排!$A:$Y,HG$2+1,FALSE),"") | HH17: =IFERROR(VLOOKUP(HH16,教师安排!$A:$Y,HH$2+1,FALSE),"") | HI17: =IFERROR(VLOOKUP(HI16,教师安排!$A:$Y,HI$2+1,FALSE),"") | HJ17: =IFERROR(VLOOKUP(HJ16,教师安排!$A:$Y,HJ$2+1,FALSE),"") | HK17: =IFERROR(VLOOKUP(HK16,教师安排!$A:$Y,HK$2+1,FALSE),"") -> 康波 | HL17: =IFERROR(VLOOKUP(HL16,教师安排!$A:$Y,HL$2+1,FALSE),"") -> 史振塞 | HM17: =IFERROR(VLOOKUP(HM16,教师安排!$A:$Y,HM$2+1,FALSE),"") -> 张喆 | HN17: =IFERROR(VLOOKUP(HN16,教师安排!$A:$Y,HN$2+1,FALSE),"") -> 刘珊珊 | ... IC17: =IFERROR(VLOOKUP(IC16,教师安排!$A:$Y,IC$2+1,FALSE),"") | IE17: =IFERROR(VLOOKUP(IE16,教师安排!$A:$Y,IE$2+1,FALSE),"") | IF17: =IFERROR(VLOOKUP(IF16,教师安排!$A:$Y,IF$2+1,FALSE),"") | IG17: =IFERROR(VLOOKUP(IG16,教师安排!$A:$Y,IG$2+1,FALSE),"") | IH17: =IFERROR(VLOOKUP(IH16,教师安排!$A:$Y,IH$2+1,FALSE),"") | II17: =IFERROR(VLOOKUP(II16,教师安排!$A:$Y,II$2+1,FALSE),"") -> 侯淑贤 | IJ17: =IFERROR(VLOOKUP(IJ16,教师安排!$A:$Y,IJ$2+1,FALSE),"") -> 岳/厉 | IK17: =IFERROR(VLOOKUP(IK16,教师安排!$A:$Y,IK$2+1,FALSE),"") -> 岳/厉 | IL17: =IFERROR(VLOOKUP(IL16,教师安排!$A:$Y,IL$2+1,FALSE),"") -> 康波 | ... JA17: =IFERROR(VLOOKUP(JA16,教师安排!$A:$Y,JA$2+1,FALSE),"") -> 厉彦龙 | JC17: =IFERROR(VLOOKUP(JC16,教师安排!$A:$Y,JC$2+1,FALSE),"") | JD17: =IFERROR(VLOOKUP(JD16,教师安排!$A:$Y,JD$2+1,FALSE),"") | JE17: =IFERROR(VLOOKUP(JE16,教师安排!$A:$Y,JE$2+1,FALSE),"") | JF17: =IFERROR(VLOOKUP(JF16,教师安排!$A:$Y,JF$2+1,FALSE),"") | JG17: =IFERROR(VLOOKUP(JG16,教师安排!$A:$Y,JG$2+1,FALSE),"") -> 岳/厉 | JH17: =IFERROR(VLOOKUP(JH16,教师安排!$A:$Y,JH$2+1,FALSE),"") -> 李会玲 | JI17: =IFERROR(VLOOKUP(JI16,教师安排!$A:$Y,JI$2+1,FALSE),"") -> 张雨晴 | JJ17: =IFERROR(VLOOKUP(JJ16,教师安排!$A:$Y,JJ$2+1,FALSE),"") -> 岳/厉 | ... JY17: =IFERROR(VLOOKUP(JY16,教师安排!$A:$Y,JY$2+1,FALSE),"") | KA17: =IFERROR(VLOOKUP(KA16,教师安排!$A:$Y,KA$2+1,FALSE),"") | KB17: =IFERROR(VLOOKUP(KB16,教师安排!$A:$Y,KB$2+1,FALSE),"") | KC17: =IFERROR(VLOOKUP(KC16,教师安排!$A:$Y,KC$2+1,FALSE),"") | KD17: =IFERROR(VLOOKUP(KD16,教师安排!$A:$Y,KD$2+1,FALSE),"")
B18: 5 | C18: 班会 | D18: 班会 | E18: 班会 | F18: 历史 | G18: 班会 | H18: 班会 | I18: 班会 | J18: 班会 | K18: 班会 | L18: 班会 | M18: 体育训练 | N18: 班会 | O18: 班会 | P18: 班会 | Q18: 班会 | AA18: 生物 | AB18: 地理 | AC18: 数学 | AD18: 语文 | AE18: 外语 | AF18: 物理 | AG18: 通用 | AH18: 外语 | AI18: 生物 | AJ18: 外语 | AK18: 体育训练 | AL18: 语文 | AM18: 政治 | AN18: 地理 | AO18: 数学 | AY18: 语文 | AZ18: 化学 | BA18: 数学 | BB18: 历史 | BC18: 外语 | BD18: 外语 | BE18: 外语 | BF18: 通用 | BG18: 生物 | BH18: 地理 | BI18: 体育训练 | BJ18: 地理 | BK18: 政治 | BL18: 语文 | BM18: 历史 | BW18: 数学 | BX18: 地理 | BY18: 语文 | BZ18: 语文 | CA18: 化学 | CB18: 生物 | CC18: 化学 | CD18: 通用 | CE18: 历史 | CF18: 历史 | CG18: 体育训练 | CH18: 语文 | CI18: 政治 | CJ18: 地理 | CK18: 地理 | CU18: 数学 | CV18: 外语 | CW18: 外语 | CX18: 语文 | CY18: 信息 | CZ18: 信息 | DA18: 物理 | DB18: 语文 | DC18: 历史 | DD18: 地理 | DE18: 体育训练 | DF18: 数学 | DG18: 数学 | DH18: 历史 | DI18: 政治 | DK18: 英语 | DM18: 俄语 | DS18: 化学 | DT18: 历史 | DU18: 数学 | DV18: 数学 | DW18: 化学 | DX18: 物理 | DY18: 语文 | DZ18: 化学 | EA18: 语文 | EB18: 语文 | EC18: 政治 | ED18: 历史 | EE18: 数学 | EF18: 地理 | EG18: 地理 | EQ18: 物理 | ER18: 外语 | ES18: 外语 | ET18: 地理 | EU18: 化学 | EV18: 生物 | EW18: 物理 | EX18: 外语 | EY18: 生物 | EZ18: 地理 | FA18: 政治 | FB18: 政治 | FC18: 数学 | FD18: 历史 | FE18: 历史 | FG18: 英语 | FI18: 俄语 | FO18: 班会 | FP18: 班会 | FQ18: 班会 | FR18: 历史 | FS18: 班会 | FT18: 班会 | FU18: 班会 | FV18: 班会 | FW18: 班会 | FX18: 班会 | FY18: 体育训练 | FZ18: 班会 | GA18: 班会 | GB18: 班会 | GC18: 班会 | GM18: 生物 | GN18: 地理 | GO18: 数学 | GP18: 语文 | GQ18: 外语 | GR18: 物理 | GS18: 通用 | GT18: 外语 | GU18: 生物 | GV18: 外语 | GW18: 体育训练 | GX18: 语文 | GY18: 政治 | GZ18: 地理 | HA18: 数学 | HK18: 语文 | HL18: 化学 | HM18: 数学 | HN18: 历史 | HO18: 外语 | HP18: 外语 | HQ18: 外语 | HR18: 通用 | HS18: 生物 | HT18: 地理 | HU18: 体育训练 | HV18: 地理 | HW18: 政治 | HX18: 语文 | HY18: 历史 | II18: 数学 | IJ18: 地理 | IK18: 语文 | IL18: 语文 | IM18: 化学 | IN18: 生物 | IO18: 化学 | IP18: 通用 | IQ18: 历史 | IR18: 历史 | IS18: 体育训练 | IT18: 语文 | IU18: 政治 | IV18: 地理 | IW18: 地理 | JG18: 地理 | JH18: 外语 | JI18: 外语 | JJ18: 语文 | JK18: 信息 | JL18: 信息 | JM18: 物理 | JN18: 语文 | JO18: 历史 | JP18: 地理 | JQ18: 体育训练 | JR18: 语文 | JS18: 数学 | JT18: 历史 | JU18: 政治 | JW18: 英语 | JY18: 俄语
